2025-07-15 07:41:09,279 ERROR scheduler Exception in Enqueue Events for Site xyz.com
Traceback (most recent call last):
  File "/home/hardikvyas/parag/frappe-bench/apps/frappe/frappe/utils/scheduler.py", line 99, in enqueue_events_for_site
    if is_scheduler_inactive():
       ^^^^^^^^^^^^^^^^^^^^^^^
  File "/home/hardikvyas/parag/frappe-bench/apps/frappe/frappe/utils/scheduler.py", line 143, in is_scheduler_inactive
    if is_scheduler_disabled(verbose=verbose):
       ^^^^^^^^^^^^^^^^^^^^^^^^^^^^^^^^^^^^^^
  File "/home/hardikvyas/parag/frappe-bench/apps/frappe/frappe/utils/scheduler.py", line 156, in is_scheduler_disabled
    frappe.db.get_single_value("System Settings", "enable_scheduler")
  File "/home/hardikvyas/parag/frappe-bench/apps/frappe/frappe/database/database.py", line 836, in get_single_value
    ).run()
      ^^^^^
  File "/home/hardikvyas/parag/frappe-bench/apps/frappe/frappe/query_builder/utils.py", line 87, in execute_query
    result = frappe.db.sql(query, params, *args, **kwargs)  # nosemgrep
             ^^^^^^^^^^^^^^^^^^^^^^^^^^^^^^^^^^^^^^^^^^^^^
  File "/home/hardikvyas/parag/frappe-bench/apps/frappe/frappe/database/database.py", line 207, in sql
    self.connect()
  File "/home/hardikvyas/parag/frappe-bench/apps/frappe/frappe/database/database.py", line 112, in connect
    self._conn: "MariadbConnection" | "PostgresConnection" = self.get_connection()
                                                             ^^^^^^^^^^^^^^^^^^^^^
  File "/home/hardikvyas/parag/frappe-bench/apps/frappe/frappe/database/mariadb/database.py", line 108, in get_connection
    conn = self._get_connection()
           ^^^^^^^^^^^^^^^^^^^^^^
  File "/home/hardikvyas/parag/frappe-bench/apps/frappe/frappe/database/mariadb/database.py", line 114, in _get_connection
    return self.create_connection()
           ^^^^^^^^^^^^^^^^^^^^^^^^
  File "/home/hardikvyas/parag/frappe-bench/apps/frappe/frappe/database/mariadb/database.py", line 117, in create_connection
    return pymysql.connect(**self.get_connection_settings())
           ^^^^^^^^^^^^^^^^^^^^^^^^^^^^^^^^^^^^^^^^^^^^^^^^^
  File "/home/hardikvyas/parag/frappe-bench/env/lib/python3.12/site-packages/pymysql/connections.py", line 361, in __init__
    self.connect()
  File "/home/hardikvyas/parag/frappe-bench/env/lib/python3.12/site-packages/pymysql/connections.py", line 669, in connect
    self._request_authentication()
  File "/home/hardikvyas/parag/frappe-bench/env/lib/python3.12/site-packages/pymysql/connections.py", line 957, in _request_authentication
    auth_packet = self._read_packet()
                  ^^^^^^^^^^^^^^^^^^^
  File "/home/hardikvyas/parag/frappe-bench/env/lib/python3.12/site-packages/pymysql/connections.py", line 775, in _read_packet
    packet.raise_for_error()
  File "/home/hardikvyas/parag/frappe-bench/env/lib/python3.12/site-packages/pymysql/protocol.py", line 219, in raise_for_error
    err.raise_mysql_exception(self._data)
  File "/home/hardikvyas/parag/frappe-bench/env/lib/python3.12/site-packages/pymysql/err.py", line 150, in raise_mysql_exception
    raise errorclass(errno, errval)
pymysql.err.OperationalError: (1698, "Access denied for user '_10095d3054764b4c'@'localhost'")
2025-07-15 07:42:03,372 ERROR scheduler Exception in Enqueue Events for Site xyz.com
Traceback (most recent call last):
  File "/home/hardikvyas/parag/frappe-bench/apps/frappe/frappe/utils/scheduler.py", line 99, in enqueue_events_for_site
    if is_scheduler_inactive():
       ^^^^^^^^^^^^^^^^^^^^^^^
  File "/home/hardikvyas/parag/frappe-bench/apps/frappe/frappe/utils/scheduler.py", line 143, in is_scheduler_inactive
    if is_scheduler_disabled(verbose=verbose):
       ^^^^^^^^^^^^^^^^^^^^^^^^^^^^^^^^^^^^^^
  File "/home/hardikvyas/parag/frappe-bench/apps/frappe/frappe/utils/scheduler.py", line 156, in is_scheduler_disabled
    frappe.db.get_single_value("System Settings", "enable_scheduler")
  File "/home/hardikvyas/parag/frappe-bench/apps/frappe/frappe/database/database.py", line 836, in get_single_value
    ).run()
      ^^^^^
  File "/home/hardikvyas/parag/frappe-bench/apps/frappe/frappe/query_builder/utils.py", line 87, in execute_query
    result = frappe.db.sql(query, params, *args, **kwargs)  # nosemgrep
             ^^^^^^^^^^^^^^^^^^^^^^^^^^^^^^^^^^^^^^^^^^^^^
  File "/home/hardikvyas/parag/frappe-bench/apps/frappe/frappe/database/database.py", line 207, in sql
    self.connect()
  File "/home/hardikvyas/parag/frappe-bench/apps/frappe/frappe/database/database.py", line 112, in connect
    self._conn: "MariadbConnection" | "PostgresConnection" = self.get_connection()
                                                             ^^^^^^^^^^^^^^^^^^^^^
  File "/home/hardikvyas/parag/frappe-bench/apps/frappe/frappe/database/mariadb/database.py", line 108, in get_connection
    conn = self._get_connection()
           ^^^^^^^^^^^^^^^^^^^^^^
  File "/home/hardikvyas/parag/frappe-bench/apps/frappe/frappe/database/mariadb/database.py", line 114, in _get_connection
    return self.create_connection()
           ^^^^^^^^^^^^^^^^^^^^^^^^
  File "/home/hardikvyas/parag/frappe-bench/apps/frappe/frappe/database/mariadb/database.py", line 117, in create_connection
    return pymysql.connect(**self.get_connection_settings())
           ^^^^^^^^^^^^^^^^^^^^^^^^^^^^^^^^^^^^^^^^^^^^^^^^^
  File "/home/hardikvyas/parag/frappe-bench/env/lib/python3.12/site-packages/pymysql/connections.py", line 361, in __init__
    self.connect()
  File "/home/hardikvyas/parag/frappe-bench/env/lib/python3.12/site-packages/pymysql/connections.py", line 669, in connect
    self._request_authentication()
  File "/home/hardikvyas/parag/frappe-bench/env/lib/python3.12/site-packages/pymysql/connections.py", line 957, in _request_authentication
    auth_packet = self._read_packet()
                  ^^^^^^^^^^^^^^^^^^^
  File "/home/hardikvyas/parag/frappe-bench/env/lib/python3.12/site-packages/pymysql/connections.py", line 775, in _read_packet
    packet.raise_for_error()
  File "/home/hardikvyas/parag/frappe-bench/env/lib/python3.12/site-packages/pymysql/protocol.py", line 219, in raise_for_error
    err.raise_mysql_exception(self._data)
  File "/home/hardikvyas/parag/frappe-bench/env/lib/python3.12/site-packages/pymysql/err.py", line 150, in raise_mysql_exception
    raise errorclass(errno, errval)
pymysql.err.OperationalError: (1698, "Access denied for user '_10095d3054764b4c'@'localhost'")
2025-07-15 07:42:57,505 ERROR scheduler Exception in Enqueue Events for Site xyz.com
Traceback (most recent call last):
  File "/home/hardikvyas/parag/frappe-bench/apps/frappe/frappe/utils/scheduler.py", line 99, in enqueue_events_for_site
    if is_scheduler_inactive():
       ^^^^^^^^^^^^^^^^^^^^^^^
  File "/home/hardikvyas/parag/frappe-bench/apps/frappe/frappe/utils/scheduler.py", line 143, in is_scheduler_inactive
    if is_scheduler_disabled(verbose=verbose):
       ^^^^^^^^^^^^^^^^^^^^^^^^^^^^^^^^^^^^^^
  File "/home/hardikvyas/parag/frappe-bench/apps/frappe/frappe/utils/scheduler.py", line 156, in is_scheduler_disabled
    frappe.db.get_single_value("System Settings", "enable_scheduler")
  File "/home/hardikvyas/parag/frappe-bench/apps/frappe/frappe/database/database.py", line 836, in get_single_value
    ).run()
      ^^^^^
  File "/home/hardikvyas/parag/frappe-bench/apps/frappe/frappe/query_builder/utils.py", line 87, in execute_query
    result = frappe.db.sql(query, params, *args, **kwargs)  # nosemgrep
             ^^^^^^^^^^^^^^^^^^^^^^^^^^^^^^^^^^^^^^^^^^^^^
  File "/home/hardikvyas/parag/frappe-bench/apps/frappe/frappe/database/database.py", line 207, in sql
    self.connect()
  File "/home/hardikvyas/parag/frappe-bench/apps/frappe/frappe/database/database.py", line 112, in connect
    self._conn: "MariadbConnection" | "PostgresConnection" = self.get_connection()
                                                             ^^^^^^^^^^^^^^^^^^^^^
  File "/home/hardikvyas/parag/frappe-bench/apps/frappe/frappe/database/mariadb/database.py", line 108, in get_connection
    conn = self._get_connection()
           ^^^^^^^^^^^^^^^^^^^^^^
  File "/home/hardikvyas/parag/frappe-bench/apps/frappe/frappe/database/mariadb/database.py", line 114, in _get_connection
    return self.create_connection()
           ^^^^^^^^^^^^^^^^^^^^^^^^
  File "/home/hardikvyas/parag/frappe-bench/apps/frappe/frappe/database/mariadb/database.py", line 117, in create_connection
    return pymysql.connect(**self.get_connection_settings())
           ^^^^^^^^^^^^^^^^^^^^^^^^^^^^^^^^^^^^^^^^^^^^^^^^^
  File "/home/hardikvyas/parag/frappe-bench/env/lib/python3.12/site-packages/pymysql/connections.py", line 361, in __init__
    self.connect()
  File "/home/hardikvyas/parag/frappe-bench/env/lib/python3.12/site-packages/pymysql/connections.py", line 669, in connect
    self._request_authentication()
  File "/home/hardikvyas/parag/frappe-bench/env/lib/python3.12/site-packages/pymysql/connections.py", line 957, in _request_authentication
    auth_packet = self._read_packet()
                  ^^^^^^^^^^^^^^^^^^^
  File "/home/hardikvyas/parag/frappe-bench/env/lib/python3.12/site-packages/pymysql/connections.py", line 775, in _read_packet
    packet.raise_for_error()
  File "/home/hardikvyas/parag/frappe-bench/env/lib/python3.12/site-packages/pymysql/protocol.py", line 219, in raise_for_error
    err.raise_mysql_exception(self._data)
  File "/home/hardikvyas/parag/frappe-bench/env/lib/python3.12/site-packages/pymysql/err.py", line 150, in raise_mysql_exception
    raise errorclass(errno, errval)
pymysql.err.OperationalError: (1698, "Access denied for user '_10095d3054764b4c'@'localhost'")
2025-07-15 07:43:54,663 ERROR scheduler Exception in Enqueue Events for Site xyz.com
Traceback (most recent call last):
  File "/home/hardikvyas/parag/frappe-bench/apps/frappe/frappe/utils/scheduler.py", line 99, in enqueue_events_for_site
    if is_scheduler_inactive():
       ^^^^^^^^^^^^^^^^^^^^^^^
  File "/home/hardikvyas/parag/frappe-bench/apps/frappe/frappe/utils/scheduler.py", line 143, in is_scheduler_inactive
    if is_scheduler_disabled(verbose=verbose):
       ^^^^^^^^^^^^^^^^^^^^^^^^^^^^^^^^^^^^^^
  File "/home/hardikvyas/parag/frappe-bench/apps/frappe/frappe/utils/scheduler.py", line 156, in is_scheduler_disabled
    frappe.db.get_single_value("System Settings", "enable_scheduler")
  File "/home/hardikvyas/parag/frappe-bench/apps/frappe/frappe/database/database.py", line 836, in get_single_value
    ).run()
      ^^^^^
  File "/home/hardikvyas/parag/frappe-bench/apps/frappe/frappe/query_builder/utils.py", line 87, in execute_query
    result = frappe.db.sql(query, params, *args, **kwargs)  # nosemgrep
             ^^^^^^^^^^^^^^^^^^^^^^^^^^^^^^^^^^^^^^^^^^^^^
  File "/home/hardikvyas/parag/frappe-bench/apps/frappe/frappe/database/database.py", line 207, in sql
    self.connect()
  File "/home/hardikvyas/parag/frappe-bench/apps/frappe/frappe/database/database.py", line 112, in connect
    self._conn: "MariadbConnection" | "PostgresConnection" = self.get_connection()
                                                             ^^^^^^^^^^^^^^^^^^^^^
  File "/home/hardikvyas/parag/frappe-bench/apps/frappe/frappe/database/mariadb/database.py", line 108, in get_connection
    conn = self._get_connection()
           ^^^^^^^^^^^^^^^^^^^^^^
  File "/home/hardikvyas/parag/frappe-bench/apps/frappe/frappe/database/mariadb/database.py", line 114, in _get_connection
    return self.create_connection()
           ^^^^^^^^^^^^^^^^^^^^^^^^
  File "/home/hardikvyas/parag/frappe-bench/apps/frappe/frappe/database/mariadb/database.py", line 117, in create_connection
    return pymysql.connect(**self.get_connection_settings())
           ^^^^^^^^^^^^^^^^^^^^^^^^^^^^^^^^^^^^^^^^^^^^^^^^^
  File "/home/hardikvyas/parag/frappe-bench/env/lib/python3.12/site-packages/pymysql/connections.py", line 361, in __init__
    self.connect()
  File "/home/hardikvyas/parag/frappe-bench/env/lib/python3.12/site-packages/pymysql/connections.py", line 669, in connect
    self._request_authentication()
  File "/home/hardikvyas/parag/frappe-bench/env/lib/python3.12/site-packages/pymysql/connections.py", line 957, in _request_authentication
    auth_packet = self._read_packet()
                  ^^^^^^^^^^^^^^^^^^^
  File "/home/hardikvyas/parag/frappe-bench/env/lib/python3.12/site-packages/pymysql/connections.py", line 775, in _read_packet
    packet.raise_for_error()
  File "/home/hardikvyas/parag/frappe-bench/env/lib/python3.12/site-packages/pymysql/protocol.py", line 219, in raise_for_error
    err.raise_mysql_exception(self._data)
  File "/home/hardikvyas/parag/frappe-bench/env/lib/python3.12/site-packages/pymysql/err.py", line 150, in raise_mysql_exception
    raise errorclass(errno, errval)
pymysql.err.OperationalError: (1698, "Access denied for user '_10095d3054764b4c'@'localhost'")
2025-07-15 07:44:48,778 ERROR scheduler Exception in Enqueue Events for Site xyz.com
Traceback (most recent call last):
  File "/home/hardikvyas/parag/frappe-bench/apps/frappe/frappe/utils/scheduler.py", line 99, in enqueue_events_for_site
    if is_scheduler_inactive():
       ^^^^^^^^^^^^^^^^^^^^^^^
  File "/home/hardikvyas/parag/frappe-bench/apps/frappe/frappe/utils/scheduler.py", line 143, in is_scheduler_inactive
    if is_scheduler_disabled(verbose=verbose):
       ^^^^^^^^^^^^^^^^^^^^^^^^^^^^^^^^^^^^^^
  File "/home/hardikvyas/parag/frappe-bench/apps/frappe/frappe/utils/scheduler.py", line 156, in is_scheduler_disabled
    frappe.db.get_single_value("System Settings", "enable_scheduler")
  File "/home/hardikvyas/parag/frappe-bench/apps/frappe/frappe/database/database.py", line 836, in get_single_value
    ).run()
      ^^^^^
  File "/home/hardikvyas/parag/frappe-bench/apps/frappe/frappe/query_builder/utils.py", line 87, in execute_query
    result = frappe.db.sql(query, params, *args, **kwargs)  # nosemgrep
             ^^^^^^^^^^^^^^^^^^^^^^^^^^^^^^^^^^^^^^^^^^^^^
  File "/home/hardikvyas/parag/frappe-bench/apps/frappe/frappe/database/database.py", line 207, in sql
    self.connect()
  File "/home/hardikvyas/parag/frappe-bench/apps/frappe/frappe/database/database.py", line 112, in connect
    self._conn: "MariadbConnection" | "PostgresConnection" = self.get_connection()
                                                             ^^^^^^^^^^^^^^^^^^^^^
  File "/home/hardikvyas/parag/frappe-bench/apps/frappe/frappe/database/mariadb/database.py", line 108, in get_connection
    conn = self._get_connection()
           ^^^^^^^^^^^^^^^^^^^^^^
  File "/home/hardikvyas/parag/frappe-bench/apps/frappe/frappe/database/mariadb/database.py", line 114, in _get_connection
    return self.create_connection()
           ^^^^^^^^^^^^^^^^^^^^^^^^
  File "/home/hardikvyas/parag/frappe-bench/apps/frappe/frappe/database/mariadb/database.py", line 117, in create_connection
    return pymysql.connect(**self.get_connection_settings())
           ^^^^^^^^^^^^^^^^^^^^^^^^^^^^^^^^^^^^^^^^^^^^^^^^^
  File "/home/hardikvyas/parag/frappe-bench/env/lib/python3.12/site-packages/pymysql/connections.py", line 361, in __init__
    self.connect()
  File "/home/hardikvyas/parag/frappe-bench/env/lib/python3.12/site-packages/pymysql/connections.py", line 669, in connect
    self._request_authentication()
  File "/home/hardikvyas/parag/frappe-bench/env/lib/python3.12/site-packages/pymysql/connections.py", line 957, in _request_authentication
    auth_packet = self._read_packet()
                  ^^^^^^^^^^^^^^^^^^^
  File "/home/hardikvyas/parag/frappe-bench/env/lib/python3.12/site-packages/pymysql/connections.py", line 775, in _read_packet
    packet.raise_for_error()
  File "/home/hardikvyas/parag/frappe-bench/env/lib/python3.12/site-packages/pymysql/protocol.py", line 219, in raise_for_error
    err.raise_mysql_exception(self._data)
  File "/home/hardikvyas/parag/frappe-bench/env/lib/python3.12/site-packages/pymysql/err.py", line 150, in raise_mysql_exception
    raise errorclass(errno, errval)
pymysql.err.OperationalError: (1698, "Access denied for user '_10095d3054764b4c'@'localhost'")
2025-07-15 07:45:42,828 ERROR scheduler Exception in Enqueue Events for Site xyz.com
Traceback (most recent call last):
  File "/home/hardikvyas/parag/frappe-bench/apps/frappe/frappe/utils/scheduler.py", line 99, in enqueue_events_for_site
    if is_scheduler_inactive():
       ^^^^^^^^^^^^^^^^^^^^^^^
  File "/home/hardikvyas/parag/frappe-bench/apps/frappe/frappe/utils/scheduler.py", line 143, in is_scheduler_inactive
    if is_scheduler_disabled(verbose=verbose):
       ^^^^^^^^^^^^^^^^^^^^^^^^^^^^^^^^^^^^^^
  File "/home/hardikvyas/parag/frappe-bench/apps/frappe/frappe/utils/scheduler.py", line 156, in is_scheduler_disabled
    frappe.db.get_single_value("System Settings", "enable_scheduler")
  File "/home/hardikvyas/parag/frappe-bench/apps/frappe/frappe/database/database.py", line 836, in get_single_value
    ).run()
      ^^^^^
  File "/home/hardikvyas/parag/frappe-bench/apps/frappe/frappe/query_builder/utils.py", line 87, in execute_query
    result = frappe.db.sql(query, params, *args, **kwargs)  # nosemgrep
             ^^^^^^^^^^^^^^^^^^^^^^^^^^^^^^^^^^^^^^^^^^^^^
  File "/home/hardikvyas/parag/frappe-bench/apps/frappe/frappe/database/database.py", line 207, in sql
    self.connect()
  File "/home/hardikvyas/parag/frappe-bench/apps/frappe/frappe/database/database.py", line 112, in connect
    self._conn: "MariadbConnection" | "PostgresConnection" = self.get_connection()
                                                             ^^^^^^^^^^^^^^^^^^^^^
  File "/home/hardikvyas/parag/frappe-bench/apps/frappe/frappe/database/mariadb/database.py", line 108, in get_connection
    conn = self._get_connection()
           ^^^^^^^^^^^^^^^^^^^^^^
  File "/home/hardikvyas/parag/frappe-bench/apps/frappe/frappe/database/mariadb/database.py", line 114, in _get_connection
    return self.create_connection()
           ^^^^^^^^^^^^^^^^^^^^^^^^
  File "/home/hardikvyas/parag/frappe-bench/apps/frappe/frappe/database/mariadb/database.py", line 117, in create_connection
    return pymysql.connect(**self.get_connection_settings())
           ^^^^^^^^^^^^^^^^^^^^^^^^^^^^^^^^^^^^^^^^^^^^^^^^^
  File "/home/hardikvyas/parag/frappe-bench/env/lib/python3.12/site-packages/pymysql/connections.py", line 361, in __init__
    self.connect()
  File "/home/hardikvyas/parag/frappe-bench/env/lib/python3.12/site-packages/pymysql/connections.py", line 669, in connect
    self._request_authentication()
  File "/home/hardikvyas/parag/frappe-bench/env/lib/python3.12/site-packages/pymysql/connections.py", line 957, in _request_authentication
    auth_packet = self._read_packet()
                  ^^^^^^^^^^^^^^^^^^^
  File "/home/hardikvyas/parag/frappe-bench/env/lib/python3.12/site-packages/pymysql/connections.py", line 775, in _read_packet
    packet.raise_for_error()
  File "/home/hardikvyas/parag/frappe-bench/env/lib/python3.12/site-packages/pymysql/protocol.py", line 219, in raise_for_error
    err.raise_mysql_exception(self._data)
  File "/home/hardikvyas/parag/frappe-bench/env/lib/python3.12/site-packages/pymysql/err.py", line 150, in raise_mysql_exception
    raise errorclass(errno, errval)
pymysql.err.OperationalError: (1698, "Access denied for user '_10095d3054764b4c'@'localhost'")
2025-07-15 07:46:36,978 ERROR scheduler Exception in Enqueue Events for Site xyz.com
Traceback (most recent call last):
  File "/home/hardikvyas/parag/frappe-bench/apps/frappe/frappe/utils/scheduler.py", line 99, in enqueue_events_for_site
    if is_scheduler_inactive():
       ^^^^^^^^^^^^^^^^^^^^^^^
  File "/home/hardikvyas/parag/frappe-bench/apps/frappe/frappe/utils/scheduler.py", line 143, in is_scheduler_inactive
    if is_scheduler_disabled(verbose=verbose):
       ^^^^^^^^^^^^^^^^^^^^^^^^^^^^^^^^^^^^^^
  File "/home/hardikvyas/parag/frappe-bench/apps/frappe/frappe/utils/scheduler.py", line 156, in is_scheduler_disabled
    frappe.db.get_single_value("System Settings", "enable_scheduler")
  File "/home/hardikvyas/parag/frappe-bench/apps/frappe/frappe/database/database.py", line 836, in get_single_value
    ).run()
      ^^^^^
  File "/home/hardikvyas/parag/frappe-bench/apps/frappe/frappe/query_builder/utils.py", line 87, in execute_query
    result = frappe.db.sql(query, params, *args, **kwargs)  # nosemgrep
             ^^^^^^^^^^^^^^^^^^^^^^^^^^^^^^^^^^^^^^^^^^^^^
  File "/home/hardikvyas/parag/frappe-bench/apps/frappe/frappe/database/database.py", line 207, in sql
    self.connect()
  File "/home/hardikvyas/parag/frappe-bench/apps/frappe/frappe/database/database.py", line 112, in connect
    self._conn: "MariadbConnection" | "PostgresConnection" = self.get_connection()
                                                             ^^^^^^^^^^^^^^^^^^^^^
  File "/home/hardikvyas/parag/frappe-bench/apps/frappe/frappe/database/mariadb/database.py", line 108, in get_connection
    conn = self._get_connection()
           ^^^^^^^^^^^^^^^^^^^^^^
  File "/home/hardikvyas/parag/frappe-bench/apps/frappe/frappe/database/mariadb/database.py", line 114, in _get_connection
    return self.create_connection()
           ^^^^^^^^^^^^^^^^^^^^^^^^
  File "/home/hardikvyas/parag/frappe-bench/apps/frappe/frappe/database/mariadb/database.py", line 117, in create_connection
    return pymysql.connect(**self.get_connection_settings())
           ^^^^^^^^^^^^^^^^^^^^^^^^^^^^^^^^^^^^^^^^^^^^^^^^^
  File "/home/hardikvyas/parag/frappe-bench/env/lib/python3.12/site-packages/pymysql/connections.py", line 361, in __init__
    self.connect()
  File "/home/hardikvyas/parag/frappe-bench/env/lib/python3.12/site-packages/pymysql/connections.py", line 669, in connect
    self._request_authentication()
  File "/home/hardikvyas/parag/frappe-bench/env/lib/python3.12/site-packages/pymysql/connections.py", line 957, in _request_authentication
    auth_packet = self._read_packet()
                  ^^^^^^^^^^^^^^^^^^^
  File "/home/hardikvyas/parag/frappe-bench/env/lib/python3.12/site-packages/pymysql/connections.py", line 775, in _read_packet
    packet.raise_for_error()
  File "/home/hardikvyas/parag/frappe-bench/env/lib/python3.12/site-packages/pymysql/protocol.py", line 219, in raise_for_error
    err.raise_mysql_exception(self._data)
  File "/home/hardikvyas/parag/frappe-bench/env/lib/python3.12/site-packages/pymysql/err.py", line 150, in raise_mysql_exception
    raise errorclass(errno, errval)
pymysql.err.OperationalError: (1698, "Access denied for user '_10095d3054764b4c'@'localhost'")
2025-07-15 07:47:34,148 ERROR scheduler Exception in Enqueue Events for Site xyz.com
Traceback (most recent call last):
  File "/home/hardikvyas/parag/frappe-bench/apps/frappe/frappe/utils/scheduler.py", line 99, in enqueue_events_for_site
    if is_scheduler_inactive():
       ^^^^^^^^^^^^^^^^^^^^^^^
  File "/home/hardikvyas/parag/frappe-bench/apps/frappe/frappe/utils/scheduler.py", line 143, in is_scheduler_inactive
    if is_scheduler_disabled(verbose=verbose):
       ^^^^^^^^^^^^^^^^^^^^^^^^^^^^^^^^^^^^^^
  File "/home/hardikvyas/parag/frappe-bench/apps/frappe/frappe/utils/scheduler.py", line 156, in is_scheduler_disabled
    frappe.db.get_single_value("System Settings", "enable_scheduler")
  File "/home/hardikvyas/parag/frappe-bench/apps/frappe/frappe/database/database.py", line 836, in get_single_value
    ).run()
      ^^^^^
  File "/home/hardikvyas/parag/frappe-bench/apps/frappe/frappe/query_builder/utils.py", line 87, in execute_query
    result = frappe.db.sql(query, params, *args, **kwargs)  # nosemgrep
             ^^^^^^^^^^^^^^^^^^^^^^^^^^^^^^^^^^^^^^^^^^^^^
  File "/home/hardikvyas/parag/frappe-bench/apps/frappe/frappe/database/database.py", line 207, in sql
    self.connect()
  File "/home/hardikvyas/parag/frappe-bench/apps/frappe/frappe/database/database.py", line 112, in connect
    self._conn: "MariadbConnection" | "PostgresConnection" = self.get_connection()
                                                             ^^^^^^^^^^^^^^^^^^^^^
  File "/home/hardikvyas/parag/frappe-bench/apps/frappe/frappe/database/mariadb/database.py", line 108, in get_connection
    conn = self._get_connection()
           ^^^^^^^^^^^^^^^^^^^^^^
  File "/home/hardikvyas/parag/frappe-bench/apps/frappe/frappe/database/mariadb/database.py", line 114, in _get_connection
    return self.create_connection()
           ^^^^^^^^^^^^^^^^^^^^^^^^
  File "/home/hardikvyas/parag/frappe-bench/apps/frappe/frappe/database/mariadb/database.py", line 117, in create_connection
    return pymysql.connect(**self.get_connection_settings())
           ^^^^^^^^^^^^^^^^^^^^^^^^^^^^^^^^^^^^^^^^^^^^^^^^^
  File "/home/hardikvyas/parag/frappe-bench/env/lib/python3.12/site-packages/pymysql/connections.py", line 361, in __init__
    self.connect()
  File "/home/hardikvyas/parag/frappe-bench/env/lib/python3.12/site-packages/pymysql/connections.py", line 669, in connect
    self._request_authentication()
  File "/home/hardikvyas/parag/frappe-bench/env/lib/python3.12/site-packages/pymysql/connections.py", line 957, in _request_authentication
    auth_packet = self._read_packet()
                  ^^^^^^^^^^^^^^^^^^^
  File "/home/hardikvyas/parag/frappe-bench/env/lib/python3.12/site-packages/pymysql/connections.py", line 775, in _read_packet
    packet.raise_for_error()
  File "/home/hardikvyas/parag/frappe-bench/env/lib/python3.12/site-packages/pymysql/protocol.py", line 219, in raise_for_error
    err.raise_mysql_exception(self._data)
  File "/home/hardikvyas/parag/frappe-bench/env/lib/python3.12/site-packages/pymysql/err.py", line 150, in raise_mysql_exception
    raise errorclass(errno, errval)
pymysql.err.OperationalError: (1698, "Access denied for user '_10095d3054764b4c'@'localhost'")
2025-07-15 07:48:26,841 ERROR scheduler Exception in Enqueue Events for Site xyz.com
Traceback (most recent call last):
  File "/home/hardikvyas/parag/frappe-bench/apps/frappe/frappe/utils/scheduler.py", line 99, in enqueue_events_for_site
    if is_scheduler_inactive():
       ^^^^^^^^^^^^^^^^^^^^^^^
  File "/home/hardikvyas/parag/frappe-bench/apps/frappe/frappe/utils/scheduler.py", line 143, in is_scheduler_inactive
    if is_scheduler_disabled(verbose=verbose):
       ^^^^^^^^^^^^^^^^^^^^^^^^^^^^^^^^^^^^^^
  File "/home/hardikvyas/parag/frappe-bench/apps/frappe/frappe/utils/scheduler.py", line 156, in is_scheduler_disabled
    frappe.db.get_single_value("System Settings", "enable_scheduler")
  File "/home/hardikvyas/parag/frappe-bench/apps/frappe/frappe/database/database.py", line 836, in get_single_value
    ).run()
      ^^^^^
  File "/home/hardikvyas/parag/frappe-bench/apps/frappe/frappe/query_builder/utils.py", line 87, in execute_query
    result = frappe.db.sql(query, params, *args, **kwargs)  # nosemgrep
             ^^^^^^^^^^^^^^^^^^^^^^^^^^^^^^^^^^^^^^^^^^^^^
  File "/home/hardikvyas/parag/frappe-bench/apps/frappe/frappe/database/database.py", line 207, in sql
    self.connect()
  File "/home/hardikvyas/parag/frappe-bench/apps/frappe/frappe/database/database.py", line 112, in connect
    self._conn: "MariadbConnection" | "PostgresConnection" = self.get_connection()
                                                             ^^^^^^^^^^^^^^^^^^^^^
  File "/home/hardikvyas/parag/frappe-bench/apps/frappe/frappe/database/mariadb/database.py", line 108, in get_connection
    conn = self._get_connection()
           ^^^^^^^^^^^^^^^^^^^^^^
  File "/home/hardikvyas/parag/frappe-bench/apps/frappe/frappe/database/mariadb/database.py", line 114, in _get_connection
    return self.create_connection()
           ^^^^^^^^^^^^^^^^^^^^^^^^
  File "/home/hardikvyas/parag/frappe-bench/apps/frappe/frappe/database/mariadb/database.py", line 117, in create_connection
    return pymysql.connect(**self.get_connection_settings())
           ^^^^^^^^^^^^^^^^^^^^^^^^^^^^^^^^^^^^^^^^^^^^^^^^^
  File "/home/hardikvyas/parag/frappe-bench/env/lib/python3.12/site-packages/pymysql/connections.py", line 361, in __init__
    self.connect()
  File "/home/hardikvyas/parag/frappe-bench/env/lib/python3.12/site-packages/pymysql/connections.py", line 669, in connect
    self._request_authentication()
  File "/home/hardikvyas/parag/frappe-bench/env/lib/python3.12/site-packages/pymysql/connections.py", line 957, in _request_authentication
    auth_packet = self._read_packet()
                  ^^^^^^^^^^^^^^^^^^^
  File "/home/hardikvyas/parag/frappe-bench/env/lib/python3.12/site-packages/pymysql/connections.py", line 775, in _read_packet
    packet.raise_for_error()
  File "/home/hardikvyas/parag/frappe-bench/env/lib/python3.12/site-packages/pymysql/protocol.py", line 219, in raise_for_error
    err.raise_mysql_exception(self._data)
  File "/home/hardikvyas/parag/frappe-bench/env/lib/python3.12/site-packages/pymysql/err.py", line 150, in raise_mysql_exception
    raise errorclass(errno, errval)
pymysql.err.OperationalError: (1698, "Access denied for user '_10095d3054764b4c'@'localhost'")
2025-07-15 07:49:20,883 ERROR scheduler Exception in Enqueue Events for Site xyz.com
Traceback (most recent call last):
  File "/home/hardikvyas/parag/frappe-bench/apps/frappe/frappe/utils/scheduler.py", line 99, in enqueue_events_for_site
    if is_scheduler_inactive():
       ^^^^^^^^^^^^^^^^^^^^^^^
  File "/home/hardikvyas/parag/frappe-bench/apps/frappe/frappe/utils/scheduler.py", line 143, in is_scheduler_inactive
    if is_scheduler_disabled(verbose=verbose):
       ^^^^^^^^^^^^^^^^^^^^^^^^^^^^^^^^^^^^^^
  File "/home/hardikvyas/parag/frappe-bench/apps/frappe/frappe/utils/scheduler.py", line 156, in is_scheduler_disabled
    frappe.db.get_single_value("System Settings", "enable_scheduler")
  File "/home/hardikvyas/parag/frappe-bench/apps/frappe/frappe/database/database.py", line 836, in get_single_value
    ).run()
      ^^^^^
  File "/home/hardikvyas/parag/frappe-bench/apps/frappe/frappe/query_builder/utils.py", line 87, in execute_query
    result = frappe.db.sql(query, params, *args, **kwargs)  # nosemgrep
             ^^^^^^^^^^^^^^^^^^^^^^^^^^^^^^^^^^^^^^^^^^^^^
  File "/home/hardikvyas/parag/frappe-bench/apps/frappe/frappe/database/database.py", line 207, in sql
    self.connect()
  File "/home/hardikvyas/parag/frappe-bench/apps/frappe/frappe/database/database.py", line 112, in connect
    self._conn: "MariadbConnection" | "PostgresConnection" = self.get_connection()
                                                             ^^^^^^^^^^^^^^^^^^^^^
  File "/home/hardikvyas/parag/frappe-bench/apps/frappe/frappe/database/mariadb/database.py", line 108, in get_connection
    conn = self._get_connection()
           ^^^^^^^^^^^^^^^^^^^^^^
  File "/home/hardikvyas/parag/frappe-bench/apps/frappe/frappe/database/mariadb/database.py", line 114, in _get_connection
    return self.create_connection()
           ^^^^^^^^^^^^^^^^^^^^^^^^
  File "/home/hardikvyas/parag/frappe-bench/apps/frappe/frappe/database/mariadb/database.py", line 117, in create_connection
    return pymysql.connect(**self.get_connection_settings())
           ^^^^^^^^^^^^^^^^^^^^^^^^^^^^^^^^^^^^^^^^^^^^^^^^^
  File "/home/hardikvyas/parag/frappe-bench/env/lib/python3.12/site-packages/pymysql/connections.py", line 361, in __init__
    self.connect()
  File "/home/hardikvyas/parag/frappe-bench/env/lib/python3.12/site-packages/pymysql/connections.py", line 669, in connect
    self._request_authentication()
  File "/home/hardikvyas/parag/frappe-bench/env/lib/python3.12/site-packages/pymysql/connections.py", line 957, in _request_authentication
    auth_packet = self._read_packet()
                  ^^^^^^^^^^^^^^^^^^^
  File "/home/hardikvyas/parag/frappe-bench/env/lib/python3.12/site-packages/pymysql/connections.py", line 775, in _read_packet
    packet.raise_for_error()
  File "/home/hardikvyas/parag/frappe-bench/env/lib/python3.12/site-packages/pymysql/protocol.py", line 219, in raise_for_error
    err.raise_mysql_exception(self._data)
  File "/home/hardikvyas/parag/frappe-bench/env/lib/python3.12/site-packages/pymysql/err.py", line 150, in raise_mysql_exception
    raise errorclass(errno, errval)
pymysql.err.OperationalError: (1698, "Access denied for user '_10095d3054764b4c'@'localhost'")
2025-07-15 07:50:15,588 ERROR scheduler Exception in Enqueue Events for Site xyz.com
Traceback (most recent call last):
  File "/home/hardikvyas/parag/frappe-bench/apps/frappe/frappe/utils/scheduler.py", line 99, in enqueue_events_for_site
    if is_scheduler_inactive():
       ^^^^^^^^^^^^^^^^^^^^^^^
  File "/home/hardikvyas/parag/frappe-bench/apps/frappe/frappe/utils/scheduler.py", line 143, in is_scheduler_inactive
    if is_scheduler_disabled(verbose=verbose):
       ^^^^^^^^^^^^^^^^^^^^^^^^^^^^^^^^^^^^^^
  File "/home/hardikvyas/parag/frappe-bench/apps/frappe/frappe/utils/scheduler.py", line 156, in is_scheduler_disabled
    frappe.db.get_single_value("System Settings", "enable_scheduler")
  File "/home/hardikvyas/parag/frappe-bench/apps/frappe/frappe/database/database.py", line 836, in get_single_value
    ).run()
      ^^^^^
  File "/home/hardikvyas/parag/frappe-bench/apps/frappe/frappe/query_builder/utils.py", line 87, in execute_query
    result = frappe.db.sql(query, params, *args, **kwargs)  # nosemgrep
             ^^^^^^^^^^^^^^^^^^^^^^^^^^^^^^^^^^^^^^^^^^^^^
  File "/home/hardikvyas/parag/frappe-bench/apps/frappe/frappe/database/database.py", line 207, in sql
    self.connect()
  File "/home/hardikvyas/parag/frappe-bench/apps/frappe/frappe/database/database.py", line 112, in connect
    self._conn: "MariadbConnection" | "PostgresConnection" = self.get_connection()
                                                             ^^^^^^^^^^^^^^^^^^^^^
  File "/home/hardikvyas/parag/frappe-bench/apps/frappe/frappe/database/mariadb/database.py", line 108, in get_connection
    conn = self._get_connection()
           ^^^^^^^^^^^^^^^^^^^^^^
  File "/home/hardikvyas/parag/frappe-bench/apps/frappe/frappe/database/mariadb/database.py", line 114, in _get_connection
    return self.create_connection()
           ^^^^^^^^^^^^^^^^^^^^^^^^
  File "/home/hardikvyas/parag/frappe-bench/apps/frappe/frappe/database/mariadb/database.py", line 117, in create_connection
    return pymysql.connect(**self.get_connection_settings())
           ^^^^^^^^^^^^^^^^^^^^^^^^^^^^^^^^^^^^^^^^^^^^^^^^^
  File "/home/hardikvyas/parag/frappe-bench/env/lib/python3.12/site-packages/pymysql/connections.py", line 361, in __init__
    self.connect()
  File "/home/hardikvyas/parag/frappe-bench/env/lib/python3.12/site-packages/pymysql/connections.py", line 669, in connect
    self._request_authentication()
  File "/home/hardikvyas/parag/frappe-bench/env/lib/python3.12/site-packages/pymysql/connections.py", line 957, in _request_authentication
    auth_packet = self._read_packet()
                  ^^^^^^^^^^^^^^^^^^^
  File "/home/hardikvyas/parag/frappe-bench/env/lib/python3.12/site-packages/pymysql/connections.py", line 775, in _read_packet
    packet.raise_for_error()
  File "/home/hardikvyas/parag/frappe-bench/env/lib/python3.12/site-packages/pymysql/protocol.py", line 219, in raise_for_error
    err.raise_mysql_exception(self._data)
  File "/home/hardikvyas/parag/frappe-bench/env/lib/python3.12/site-packages/pymysql/err.py", line 150, in raise_mysql_exception
    raise errorclass(errno, errval)
pymysql.err.OperationalError: (1698, "Access denied for user '_10095d3054764b4c'@'localhost'")
2025-07-15 07:52:28,598 ERROR scheduler Exception in Enqueue Events for Site xyz.com
Traceback (most recent call last):
  File "/home/hardikvyas/parag/frappe-bench/apps/frappe/frappe/utils/scheduler.py", line 99, in enqueue_events_for_site
    if is_scheduler_inactive():
       ^^^^^^^^^^^^^^^^^^^^^^^
  File "/home/hardikvyas/parag/frappe-bench/apps/frappe/frappe/utils/scheduler.py", line 143, in is_scheduler_inactive
    if is_scheduler_disabled(verbose=verbose):
       ^^^^^^^^^^^^^^^^^^^^^^^^^^^^^^^^^^^^^^
  File "/home/hardikvyas/parag/frappe-bench/apps/frappe/frappe/utils/scheduler.py", line 156, in is_scheduler_disabled
    frappe.db.get_single_value("System Settings", "enable_scheduler")
  File "/home/hardikvyas/parag/frappe-bench/apps/frappe/frappe/database/database.py", line 836, in get_single_value
    ).run()
      ^^^^^
  File "/home/hardikvyas/parag/frappe-bench/apps/frappe/frappe/query_builder/utils.py", line 87, in execute_query
    result = frappe.db.sql(query, params, *args, **kwargs)  # nosemgrep
             ^^^^^^^^^^^^^^^^^^^^^^^^^^^^^^^^^^^^^^^^^^^^^
  File "/home/hardikvyas/parag/frappe-bench/apps/frappe/frappe/database/database.py", line 207, in sql
    self.connect()
  File "/home/hardikvyas/parag/frappe-bench/apps/frappe/frappe/database/database.py", line 112, in connect
    self._conn: "MariadbConnection" | "PostgresConnection" = self.get_connection()
                                                             ^^^^^^^^^^^^^^^^^^^^^
  File "/home/hardikvyas/parag/frappe-bench/apps/frappe/frappe/database/mariadb/database.py", line 108, in get_connection
    conn = self._get_connection()
           ^^^^^^^^^^^^^^^^^^^^^^
  File "/home/hardikvyas/parag/frappe-bench/apps/frappe/frappe/database/mariadb/database.py", line 114, in _get_connection
    return self.create_connection()
           ^^^^^^^^^^^^^^^^^^^^^^^^
  File "/home/hardikvyas/parag/frappe-bench/apps/frappe/frappe/database/mariadb/database.py", line 117, in create_connection
    return pymysql.connect(**self.get_connection_settings())
           ^^^^^^^^^^^^^^^^^^^^^^^^^^^^^^^^^^^^^^^^^^^^^^^^^
  File "/home/hardikvyas/parag/frappe-bench/env/lib/python3.12/site-packages/pymysql/connections.py", line 361, in __init__
    self.connect()
  File "/home/hardikvyas/parag/frappe-bench/env/lib/python3.12/site-packages/pymysql/connections.py", line 669, in connect
    self._request_authentication()
  File "/home/hardikvyas/parag/frappe-bench/env/lib/python3.12/site-packages/pymysql/connections.py", line 957, in _request_authentication
    auth_packet = self._read_packet()
                  ^^^^^^^^^^^^^^^^^^^
  File "/home/hardikvyas/parag/frappe-bench/env/lib/python3.12/site-packages/pymysql/connections.py", line 775, in _read_packet
    packet.raise_for_error()
  File "/home/hardikvyas/parag/frappe-bench/env/lib/python3.12/site-packages/pymysql/protocol.py", line 219, in raise_for_error
    err.raise_mysql_exception(self._data)
  File "/home/hardikvyas/parag/frappe-bench/env/lib/python3.12/site-packages/pymysql/err.py", line 150, in raise_mysql_exception
    raise errorclass(errno, errval)
pymysql.err.OperationalError: (1698, "Access denied for user '_10095d3054764b4c'@'localhost'")
2025-07-15 07:53:23,384 ERROR scheduler Exception in Enqueue Events for Site xyz.com
Traceback (most recent call last):
  File "/home/hardikvyas/parag/frappe-bench/apps/frappe/frappe/utils/scheduler.py", line 99, in enqueue_events_for_site
    if is_scheduler_inactive():
       ^^^^^^^^^^^^^^^^^^^^^^^
  File "/home/hardikvyas/parag/frappe-bench/apps/frappe/frappe/utils/scheduler.py", line 143, in is_scheduler_inactive
    if is_scheduler_disabled(verbose=verbose):
       ^^^^^^^^^^^^^^^^^^^^^^^^^^^^^^^^^^^^^^
  File "/home/hardikvyas/parag/frappe-bench/apps/frappe/frappe/utils/scheduler.py", line 156, in is_scheduler_disabled
    frappe.db.get_single_value("System Settings", "enable_scheduler")
  File "/home/hardikvyas/parag/frappe-bench/apps/frappe/frappe/database/database.py", line 836, in get_single_value
    ).run()
      ^^^^^
  File "/home/hardikvyas/parag/frappe-bench/apps/frappe/frappe/query_builder/utils.py", line 87, in execute_query
    result = frappe.db.sql(query, params, *args, **kwargs)  # nosemgrep
             ^^^^^^^^^^^^^^^^^^^^^^^^^^^^^^^^^^^^^^^^^^^^^
  File "/home/hardikvyas/parag/frappe-bench/apps/frappe/frappe/database/database.py", line 207, in sql
    self.connect()
  File "/home/hardikvyas/parag/frappe-bench/apps/frappe/frappe/database/database.py", line 112, in connect
    self._conn: "MariadbConnection" | "PostgresConnection" = self.get_connection()
                                                             ^^^^^^^^^^^^^^^^^^^^^
  File "/home/hardikvyas/parag/frappe-bench/apps/frappe/frappe/database/mariadb/database.py", line 108, in get_connection
    conn = self._get_connection()
           ^^^^^^^^^^^^^^^^^^^^^^
  File "/home/hardikvyas/parag/frappe-bench/apps/frappe/frappe/database/mariadb/database.py", line 114, in _get_connection
    return self.create_connection()
           ^^^^^^^^^^^^^^^^^^^^^^^^
  File "/home/hardikvyas/parag/frappe-bench/apps/frappe/frappe/database/mariadb/database.py", line 117, in create_connection
    return pymysql.connect(**self.get_connection_settings())
           ^^^^^^^^^^^^^^^^^^^^^^^^^^^^^^^^^^^^^^^^^^^^^^^^^
  File "/home/hardikvyas/parag/frappe-bench/env/lib/python3.12/site-packages/pymysql/connections.py", line 361, in __init__
    self.connect()
  File "/home/hardikvyas/parag/frappe-bench/env/lib/python3.12/site-packages/pymysql/connections.py", line 669, in connect
    self._request_authentication()
  File "/home/hardikvyas/parag/frappe-bench/env/lib/python3.12/site-packages/pymysql/connections.py", line 957, in _request_authentication
    auth_packet = self._read_packet()
                  ^^^^^^^^^^^^^^^^^^^
  File "/home/hardikvyas/parag/frappe-bench/env/lib/python3.12/site-packages/pymysql/connections.py", line 775, in _read_packet
    packet.raise_for_error()
  File "/home/hardikvyas/parag/frappe-bench/env/lib/python3.12/site-packages/pymysql/protocol.py", line 219, in raise_for_error
    err.raise_mysql_exception(self._data)
  File "/home/hardikvyas/parag/frappe-bench/env/lib/python3.12/site-packages/pymysql/err.py", line 150, in raise_mysql_exception
    raise errorclass(errno, errval)
pymysql.err.OperationalError: (1698, "Access denied for user '_10095d3054764b4c'@'localhost'")
2025-07-15 07:54:17,392 ERROR scheduler Exception in Enqueue Events for Site xyz.com
Traceback (most recent call last):
  File "/home/hardikvyas/parag/frappe-bench/apps/frappe/frappe/utils/scheduler.py", line 99, in enqueue_events_for_site
    if is_scheduler_inactive():
       ^^^^^^^^^^^^^^^^^^^^^^^
  File "/home/hardikvyas/parag/frappe-bench/apps/frappe/frappe/utils/scheduler.py", line 143, in is_scheduler_inactive
    if is_scheduler_disabled(verbose=verbose):
       ^^^^^^^^^^^^^^^^^^^^^^^^^^^^^^^^^^^^^^
  File "/home/hardikvyas/parag/frappe-bench/apps/frappe/frappe/utils/scheduler.py", line 156, in is_scheduler_disabled
    frappe.db.get_single_value("System Settings", "enable_scheduler")
  File "/home/hardikvyas/parag/frappe-bench/apps/frappe/frappe/database/database.py", line 836, in get_single_value
    ).run()
      ^^^^^
  File "/home/hardikvyas/parag/frappe-bench/apps/frappe/frappe/query_builder/utils.py", line 87, in execute_query
    result = frappe.db.sql(query, params, *args, **kwargs)  # nosemgrep
             ^^^^^^^^^^^^^^^^^^^^^^^^^^^^^^^^^^^^^^^^^^^^^
  File "/home/hardikvyas/parag/frappe-bench/apps/frappe/frappe/database/database.py", line 207, in sql
    self.connect()
  File "/home/hardikvyas/parag/frappe-bench/apps/frappe/frappe/database/database.py", line 112, in connect
    self._conn: "MariadbConnection" | "PostgresConnection" = self.get_connection()
                                                             ^^^^^^^^^^^^^^^^^^^^^
  File "/home/hardikvyas/parag/frappe-bench/apps/frappe/frappe/database/mariadb/database.py", line 108, in get_connection
    conn = self._get_connection()
           ^^^^^^^^^^^^^^^^^^^^^^
  File "/home/hardikvyas/parag/frappe-bench/apps/frappe/frappe/database/mariadb/database.py", line 114, in _get_connection
    return self.create_connection()
           ^^^^^^^^^^^^^^^^^^^^^^^^
  File "/home/hardikvyas/parag/frappe-bench/apps/frappe/frappe/database/mariadb/database.py", line 117, in create_connection
    return pymysql.connect(**self.get_connection_settings())
           ^^^^^^^^^^^^^^^^^^^^^^^^^^^^^^^^^^^^^^^^^^^^^^^^^
  File "/home/hardikvyas/parag/frappe-bench/env/lib/python3.12/site-packages/pymysql/connections.py", line 361, in __init__
    self.connect()
  File "/home/hardikvyas/parag/frappe-bench/env/lib/python3.12/site-packages/pymysql/connections.py", line 669, in connect
    self._request_authentication()
  File "/home/hardikvyas/parag/frappe-bench/env/lib/python3.12/site-packages/pymysql/connections.py", line 957, in _request_authentication
    auth_packet = self._read_packet()
                  ^^^^^^^^^^^^^^^^^^^
  File "/home/hardikvyas/parag/frappe-bench/env/lib/python3.12/site-packages/pymysql/connections.py", line 775, in _read_packet
    packet.raise_for_error()
  File "/home/hardikvyas/parag/frappe-bench/env/lib/python3.12/site-packages/pymysql/protocol.py", line 219, in raise_for_error
    err.raise_mysql_exception(self._data)
  File "/home/hardikvyas/parag/frappe-bench/env/lib/python3.12/site-packages/pymysql/err.py", line 150, in raise_mysql_exception
    raise errorclass(errno, errval)
pymysql.err.OperationalError: (1698, "Access denied for user '_10095d3054764b4c'@'localhost'")
2025-07-15 07:55:11,500 ERROR scheduler Exception in Enqueue Events for Site xyz.com
Traceback (most recent call last):
  File "/home/hardikvyas/parag/frappe-bench/apps/frappe/frappe/utils/scheduler.py", line 99, in enqueue_events_for_site
    if is_scheduler_inactive():
       ^^^^^^^^^^^^^^^^^^^^^^^
  File "/home/hardikvyas/parag/frappe-bench/apps/frappe/frappe/utils/scheduler.py", line 143, in is_scheduler_inactive
    if is_scheduler_disabled(verbose=verbose):
       ^^^^^^^^^^^^^^^^^^^^^^^^^^^^^^^^^^^^^^
  File "/home/hardikvyas/parag/frappe-bench/apps/frappe/frappe/utils/scheduler.py", line 156, in is_scheduler_disabled
    frappe.db.get_single_value("System Settings", "enable_scheduler")
  File "/home/hardikvyas/parag/frappe-bench/apps/frappe/frappe/database/database.py", line 836, in get_single_value
    ).run()
      ^^^^^
  File "/home/hardikvyas/parag/frappe-bench/apps/frappe/frappe/query_builder/utils.py", line 87, in execute_query
    result = frappe.db.sql(query, params, *args, **kwargs)  # nosemgrep
             ^^^^^^^^^^^^^^^^^^^^^^^^^^^^^^^^^^^^^^^^^^^^^
  File "/home/hardikvyas/parag/frappe-bench/apps/frappe/frappe/database/database.py", line 207, in sql
    self.connect()
  File "/home/hardikvyas/parag/frappe-bench/apps/frappe/frappe/database/database.py", line 112, in connect
    self._conn: "MariadbConnection" | "PostgresConnection" = self.get_connection()
                                                             ^^^^^^^^^^^^^^^^^^^^^
  File "/home/hardikvyas/parag/frappe-bench/apps/frappe/frappe/database/mariadb/database.py", line 108, in get_connection
    conn = self._get_connection()
           ^^^^^^^^^^^^^^^^^^^^^^
  File "/home/hardikvyas/parag/frappe-bench/apps/frappe/frappe/database/mariadb/database.py", line 114, in _get_connection
    return self.create_connection()
           ^^^^^^^^^^^^^^^^^^^^^^^^
  File "/home/hardikvyas/parag/frappe-bench/apps/frappe/frappe/database/mariadb/database.py", line 117, in create_connection
    return pymysql.connect(**self.get_connection_settings())
           ^^^^^^^^^^^^^^^^^^^^^^^^^^^^^^^^^^^^^^^^^^^^^^^^^
  File "/home/hardikvyas/parag/frappe-bench/env/lib/python3.12/site-packages/pymysql/connections.py", line 361, in __init__
    self.connect()
  File "/home/hardikvyas/parag/frappe-bench/env/lib/python3.12/site-packages/pymysql/connections.py", line 669, in connect
    self._request_authentication()
  File "/home/hardikvyas/parag/frappe-bench/env/lib/python3.12/site-packages/pymysql/connections.py", line 957, in _request_authentication
    auth_packet = self._read_packet()
                  ^^^^^^^^^^^^^^^^^^^
  File "/home/hardikvyas/parag/frappe-bench/env/lib/python3.12/site-packages/pymysql/connections.py", line 775, in _read_packet
    packet.raise_for_error()
  File "/home/hardikvyas/parag/frappe-bench/env/lib/python3.12/site-packages/pymysql/protocol.py", line 219, in raise_for_error
    err.raise_mysql_exception(self._data)
  File "/home/hardikvyas/parag/frappe-bench/env/lib/python3.12/site-packages/pymysql/err.py", line 150, in raise_mysql_exception
    raise errorclass(errno, errval)
pymysql.err.OperationalError: (1698, "Access denied for user '_10095d3054764b4c'@'localhost'")
2025-07-15 07:56:08,600 ERROR scheduler Exception in Enqueue Events for Site xyz.com
Traceback (most recent call last):
  File "/home/hardikvyas/parag/frappe-bench/apps/frappe/frappe/utils/scheduler.py", line 99, in enqueue_events_for_site
    if is_scheduler_inactive():
       ^^^^^^^^^^^^^^^^^^^^^^^
  File "/home/hardikvyas/parag/frappe-bench/apps/frappe/frappe/utils/scheduler.py", line 143, in is_scheduler_inactive
    if is_scheduler_disabled(verbose=verbose):
       ^^^^^^^^^^^^^^^^^^^^^^^^^^^^^^^^^^^^^^
  File "/home/hardikvyas/parag/frappe-bench/apps/frappe/frappe/utils/scheduler.py", line 156, in is_scheduler_disabled
    frappe.db.get_single_value("System Settings", "enable_scheduler")
  File "/home/hardikvyas/parag/frappe-bench/apps/frappe/frappe/database/database.py", line 836, in get_single_value
    ).run()
      ^^^^^
  File "/home/hardikvyas/parag/frappe-bench/apps/frappe/frappe/query_builder/utils.py", line 87, in execute_query
    result = frappe.db.sql(query, params, *args, **kwargs)  # nosemgrep
             ^^^^^^^^^^^^^^^^^^^^^^^^^^^^^^^^^^^^^^^^^^^^^
  File "/home/hardikvyas/parag/frappe-bench/apps/frappe/frappe/database/database.py", line 207, in sql
    self.connect()
  File "/home/hardikvyas/parag/frappe-bench/apps/frappe/frappe/database/database.py", line 112, in connect
    self._conn: "MariadbConnection" | "PostgresConnection" = self.get_connection()
                                                             ^^^^^^^^^^^^^^^^^^^^^
  File "/home/hardikvyas/parag/frappe-bench/apps/frappe/frappe/database/mariadb/database.py", line 108, in get_connection
    conn = self._get_connection()
           ^^^^^^^^^^^^^^^^^^^^^^
  File "/home/hardikvyas/parag/frappe-bench/apps/frappe/frappe/database/mariadb/database.py", line 114, in _get_connection
    return self.create_connection()
           ^^^^^^^^^^^^^^^^^^^^^^^^
  File "/home/hardikvyas/parag/frappe-bench/apps/frappe/frappe/database/mariadb/database.py", line 117, in create_connection
    return pymysql.connect(**self.get_connection_settings())
           ^^^^^^^^^^^^^^^^^^^^^^^^^^^^^^^^^^^^^^^^^^^^^^^^^
  File "/home/hardikvyas/parag/frappe-bench/env/lib/python3.12/site-packages/pymysql/connections.py", line 361, in __init__
    self.connect()
  File "/home/hardikvyas/parag/frappe-bench/env/lib/python3.12/site-packages/pymysql/connections.py", line 669, in connect
    self._request_authentication()
  File "/home/hardikvyas/parag/frappe-bench/env/lib/python3.12/site-packages/pymysql/connections.py", line 957, in _request_authentication
    auth_packet = self._read_packet()
                  ^^^^^^^^^^^^^^^^^^^
  File "/home/hardikvyas/parag/frappe-bench/env/lib/python3.12/site-packages/pymysql/connections.py", line 775, in _read_packet
    packet.raise_for_error()
  File "/home/hardikvyas/parag/frappe-bench/env/lib/python3.12/site-packages/pymysql/protocol.py", line 219, in raise_for_error
    err.raise_mysql_exception(self._data)
  File "/home/hardikvyas/parag/frappe-bench/env/lib/python3.12/site-packages/pymysql/err.py", line 150, in raise_mysql_exception
    raise errorclass(errno, errval)
pymysql.err.OperationalError: (1698, "Access denied for user '_10095d3054764b4c'@'localhost'")
2025-07-15 07:57:02,937 ERROR scheduler Exception in Enqueue Events for Site xyz.com
Traceback (most recent call last):
  File "/home/hardikvyas/parag/frappe-bench/apps/frappe/frappe/utils/scheduler.py", line 99, in enqueue_events_for_site
    if is_scheduler_inactive():
       ^^^^^^^^^^^^^^^^^^^^^^^
  File "/home/hardikvyas/parag/frappe-bench/apps/frappe/frappe/utils/scheduler.py", line 143, in is_scheduler_inactive
    if is_scheduler_disabled(verbose=verbose):
       ^^^^^^^^^^^^^^^^^^^^^^^^^^^^^^^^^^^^^^
  File "/home/hardikvyas/parag/frappe-bench/apps/frappe/frappe/utils/scheduler.py", line 156, in is_scheduler_disabled
    frappe.db.get_single_value("System Settings", "enable_scheduler")
  File "/home/hardikvyas/parag/frappe-bench/apps/frappe/frappe/database/database.py", line 836, in get_single_value
    ).run()
      ^^^^^
  File "/home/hardikvyas/parag/frappe-bench/apps/frappe/frappe/query_builder/utils.py", line 87, in execute_query
    result = frappe.db.sql(query, params, *args, **kwargs)  # nosemgrep
             ^^^^^^^^^^^^^^^^^^^^^^^^^^^^^^^^^^^^^^^^^^^^^
  File "/home/hardikvyas/parag/frappe-bench/apps/frappe/frappe/database/database.py", line 207, in sql
    self.connect()
  File "/home/hardikvyas/parag/frappe-bench/apps/frappe/frappe/database/database.py", line 112, in connect
    self._conn: "MariadbConnection" | "PostgresConnection" = self.get_connection()
                                                             ^^^^^^^^^^^^^^^^^^^^^
  File "/home/hardikvyas/parag/frappe-bench/apps/frappe/frappe/database/mariadb/database.py", line 108, in get_connection
    conn = self._get_connection()
           ^^^^^^^^^^^^^^^^^^^^^^
  File "/home/hardikvyas/parag/frappe-bench/apps/frappe/frappe/database/mariadb/database.py", line 114, in _get_connection
    return self.create_connection()
           ^^^^^^^^^^^^^^^^^^^^^^^^
  File "/home/hardikvyas/parag/frappe-bench/apps/frappe/frappe/database/mariadb/database.py", line 117, in create_connection
    return pymysql.connect(**self.get_connection_settings())
           ^^^^^^^^^^^^^^^^^^^^^^^^^^^^^^^^^^^^^^^^^^^^^^^^^
  File "/home/hardikvyas/parag/frappe-bench/env/lib/python3.12/site-packages/pymysql/connections.py", line 361, in __init__
    self.connect()
  File "/home/hardikvyas/parag/frappe-bench/env/lib/python3.12/site-packages/pymysql/connections.py", line 669, in connect
    self._request_authentication()
  File "/home/hardikvyas/parag/frappe-bench/env/lib/python3.12/site-packages/pymysql/connections.py", line 957, in _request_authentication
    auth_packet = self._read_packet()
                  ^^^^^^^^^^^^^^^^^^^
  File "/home/hardikvyas/parag/frappe-bench/env/lib/python3.12/site-packages/pymysql/connections.py", line 775, in _read_packet
    packet.raise_for_error()
  File "/home/hardikvyas/parag/frappe-bench/env/lib/python3.12/site-packages/pymysql/protocol.py", line 219, in raise_for_error
    err.raise_mysql_exception(self._data)
  File "/home/hardikvyas/parag/frappe-bench/env/lib/python3.12/site-packages/pymysql/err.py", line 150, in raise_mysql_exception
    raise errorclass(errno, errval)
pymysql.err.OperationalError: (1698, "Access denied for user '_10095d3054764b4c'@'localhost'")
2025-07-15 07:57:57,420 ERROR scheduler Exception in Enqueue Events for Site xyz.com
Traceback (most recent call last):
  File "/home/hardikvyas/parag/frappe-bench/apps/frappe/frappe/utils/scheduler.py", line 99, in enqueue_events_for_site
    if is_scheduler_inactive():
       ^^^^^^^^^^^^^^^^^^^^^^^
  File "/home/hardikvyas/parag/frappe-bench/apps/frappe/frappe/utils/scheduler.py", line 143, in is_scheduler_inactive
    if is_scheduler_disabled(verbose=verbose):
       ^^^^^^^^^^^^^^^^^^^^^^^^^^^^^^^^^^^^^^
  File "/home/hardikvyas/parag/frappe-bench/apps/frappe/frappe/utils/scheduler.py", line 156, in is_scheduler_disabled
    frappe.db.get_single_value("System Settings", "enable_scheduler")
  File "/home/hardikvyas/parag/frappe-bench/apps/frappe/frappe/database/database.py", line 836, in get_single_value
    ).run()
      ^^^^^
  File "/home/hardikvyas/parag/frappe-bench/apps/frappe/frappe/query_builder/utils.py", line 87, in execute_query
    result = frappe.db.sql(query, params, *args, **kwargs)  # nosemgrep
             ^^^^^^^^^^^^^^^^^^^^^^^^^^^^^^^^^^^^^^^^^^^^^
  File "/home/hardikvyas/parag/frappe-bench/apps/frappe/frappe/database/database.py", line 207, in sql
    self.connect()
  File "/home/hardikvyas/parag/frappe-bench/apps/frappe/frappe/database/database.py", line 112, in connect
    self._conn: "MariadbConnection" | "PostgresConnection" = self.get_connection()
                                                             ^^^^^^^^^^^^^^^^^^^^^
  File "/home/hardikvyas/parag/frappe-bench/apps/frappe/frappe/database/mariadb/database.py", line 108, in get_connection
    conn = self._get_connection()
           ^^^^^^^^^^^^^^^^^^^^^^
  File "/home/hardikvyas/parag/frappe-bench/apps/frappe/frappe/database/mariadb/database.py", line 114, in _get_connection
    return self.create_connection()
           ^^^^^^^^^^^^^^^^^^^^^^^^
  File "/home/hardikvyas/parag/frappe-bench/apps/frappe/frappe/database/mariadb/database.py", line 117, in create_connection
    return pymysql.connect(**self.get_connection_settings())
           ^^^^^^^^^^^^^^^^^^^^^^^^^^^^^^^^^^^^^^^^^^^^^^^^^
  File "/home/hardikvyas/parag/frappe-bench/env/lib/python3.12/site-packages/pymysql/connections.py", line 361, in __init__
    self.connect()
  File "/home/hardikvyas/parag/frappe-bench/env/lib/python3.12/site-packages/pymysql/connections.py", line 669, in connect
    self._request_authentication()
  File "/home/hardikvyas/parag/frappe-bench/env/lib/python3.12/site-packages/pymysql/connections.py", line 957, in _request_authentication
    auth_packet = self._read_packet()
                  ^^^^^^^^^^^^^^^^^^^
  File "/home/hardikvyas/parag/frappe-bench/env/lib/python3.12/site-packages/pymysql/connections.py", line 775, in _read_packet
    packet.raise_for_error()
  File "/home/hardikvyas/parag/frappe-bench/env/lib/python3.12/site-packages/pymysql/protocol.py", line 219, in raise_for_error
    err.raise_mysql_exception(self._data)
  File "/home/hardikvyas/parag/frappe-bench/env/lib/python3.12/site-packages/pymysql/err.py", line 150, in raise_mysql_exception
    raise errorclass(errno, errval)
pymysql.err.OperationalError: (1698, "Access denied for user '_10095d3054764b4c'@'localhost'")
2025-07-15 07:58:51,545 ERROR scheduler Exception in Enqueue Events for Site xyz.com
Traceback (most recent call last):
  File "/home/hardikvyas/parag/frappe-bench/apps/frappe/frappe/utils/scheduler.py", line 99, in enqueue_events_for_site
    if is_scheduler_inactive():
       ^^^^^^^^^^^^^^^^^^^^^^^
  File "/home/hardikvyas/parag/frappe-bench/apps/frappe/frappe/utils/scheduler.py", line 143, in is_scheduler_inactive
    if is_scheduler_disabled(verbose=verbose):
       ^^^^^^^^^^^^^^^^^^^^^^^^^^^^^^^^^^^^^^
  File "/home/hardikvyas/parag/frappe-bench/apps/frappe/frappe/utils/scheduler.py", line 156, in is_scheduler_disabled
    frappe.db.get_single_value("System Settings", "enable_scheduler")
  File "/home/hardikvyas/parag/frappe-bench/apps/frappe/frappe/database/database.py", line 836, in get_single_value
    ).run()
      ^^^^^
  File "/home/hardikvyas/parag/frappe-bench/apps/frappe/frappe/query_builder/utils.py", line 87, in execute_query
    result = frappe.db.sql(query, params, *args, **kwargs)  # nosemgrep
             ^^^^^^^^^^^^^^^^^^^^^^^^^^^^^^^^^^^^^^^^^^^^^
  File "/home/hardikvyas/parag/frappe-bench/apps/frappe/frappe/database/database.py", line 207, in sql
    self.connect()
  File "/home/hardikvyas/parag/frappe-bench/apps/frappe/frappe/database/database.py", line 112, in connect
    self._conn: "MariadbConnection" | "PostgresConnection" = self.get_connection()
                                                             ^^^^^^^^^^^^^^^^^^^^^
  File "/home/hardikvyas/parag/frappe-bench/apps/frappe/frappe/database/mariadb/database.py", line 108, in get_connection
    conn = self._get_connection()
           ^^^^^^^^^^^^^^^^^^^^^^
  File "/home/hardikvyas/parag/frappe-bench/apps/frappe/frappe/database/mariadb/database.py", line 114, in _get_connection
    return self.create_connection()
           ^^^^^^^^^^^^^^^^^^^^^^^^
  File "/home/hardikvyas/parag/frappe-bench/apps/frappe/frappe/database/mariadb/database.py", line 117, in create_connection
    return pymysql.connect(**self.get_connection_settings())
           ^^^^^^^^^^^^^^^^^^^^^^^^^^^^^^^^^^^^^^^^^^^^^^^^^
  File "/home/hardikvyas/parag/frappe-bench/env/lib/python3.12/site-packages/pymysql/connections.py", line 361, in __init__
    self.connect()
  File "/home/hardikvyas/parag/frappe-bench/env/lib/python3.12/site-packages/pymysql/connections.py", line 669, in connect
    self._request_authentication()
  File "/home/hardikvyas/parag/frappe-bench/env/lib/python3.12/site-packages/pymysql/connections.py", line 957, in _request_authentication
    auth_packet = self._read_packet()
                  ^^^^^^^^^^^^^^^^^^^
  File "/home/hardikvyas/parag/frappe-bench/env/lib/python3.12/site-packages/pymysql/connections.py", line 775, in _read_packet
    packet.raise_for_error()
  File "/home/hardikvyas/parag/frappe-bench/env/lib/python3.12/site-packages/pymysql/protocol.py", line 219, in raise_for_error
    err.raise_mysql_exception(self._data)
  File "/home/hardikvyas/parag/frappe-bench/env/lib/python3.12/site-packages/pymysql/err.py", line 150, in raise_mysql_exception
    raise errorclass(errno, errval)
pymysql.err.OperationalError: (1698, "Access denied for user '_10095d3054764b4c'@'localhost'")
2025-07-15 07:59:45,637 ERROR scheduler Exception in Enqueue Events for Site xyz.com
Traceback (most recent call last):
  File "/home/hardikvyas/parag/frappe-bench/apps/frappe/frappe/utils/scheduler.py", line 99, in enqueue_events_for_site
    if is_scheduler_inactive():
       ^^^^^^^^^^^^^^^^^^^^^^^
  File "/home/hardikvyas/parag/frappe-bench/apps/frappe/frappe/utils/scheduler.py", line 143, in is_scheduler_inactive
    if is_scheduler_disabled(verbose=verbose):
       ^^^^^^^^^^^^^^^^^^^^^^^^^^^^^^^^^^^^^^
  File "/home/hardikvyas/parag/frappe-bench/apps/frappe/frappe/utils/scheduler.py", line 156, in is_scheduler_disabled
    frappe.db.get_single_value("System Settings", "enable_scheduler")
  File "/home/hardikvyas/parag/frappe-bench/apps/frappe/frappe/database/database.py", line 836, in get_single_value
    ).run()
      ^^^^^
  File "/home/hardikvyas/parag/frappe-bench/apps/frappe/frappe/query_builder/utils.py", line 87, in execute_query
    result = frappe.db.sql(query, params, *args, **kwargs)  # nosemgrep
             ^^^^^^^^^^^^^^^^^^^^^^^^^^^^^^^^^^^^^^^^^^^^^
  File "/home/hardikvyas/parag/frappe-bench/apps/frappe/frappe/database/database.py", line 207, in sql
    self.connect()
  File "/home/hardikvyas/parag/frappe-bench/apps/frappe/frappe/database/database.py", line 112, in connect
    self._conn: "MariadbConnection" | "PostgresConnection" = self.get_connection()
                                                             ^^^^^^^^^^^^^^^^^^^^^
  File "/home/hardikvyas/parag/frappe-bench/apps/frappe/frappe/database/mariadb/database.py", line 108, in get_connection
    conn = self._get_connection()
           ^^^^^^^^^^^^^^^^^^^^^^
  File "/home/hardikvyas/parag/frappe-bench/apps/frappe/frappe/database/mariadb/database.py", line 114, in _get_connection
    return self.create_connection()
           ^^^^^^^^^^^^^^^^^^^^^^^^
  File "/home/hardikvyas/parag/frappe-bench/apps/frappe/frappe/database/mariadb/database.py", line 117, in create_connection
    return pymysql.connect(**self.get_connection_settings())
           ^^^^^^^^^^^^^^^^^^^^^^^^^^^^^^^^^^^^^^^^^^^^^^^^^
  File "/home/hardikvyas/parag/frappe-bench/env/lib/python3.12/site-packages/pymysql/connections.py", line 361, in __init__
    self.connect()
  File "/home/hardikvyas/parag/frappe-bench/env/lib/python3.12/site-packages/pymysql/connections.py", line 669, in connect
    self._request_authentication()
  File "/home/hardikvyas/parag/frappe-bench/env/lib/python3.12/site-packages/pymysql/connections.py", line 957, in _request_authentication
    auth_packet = self._read_packet()
                  ^^^^^^^^^^^^^^^^^^^
  File "/home/hardikvyas/parag/frappe-bench/env/lib/python3.12/site-packages/pymysql/connections.py", line 775, in _read_packet
    packet.raise_for_error()
  File "/home/hardikvyas/parag/frappe-bench/env/lib/python3.12/site-packages/pymysql/protocol.py", line 219, in raise_for_error
    err.raise_mysql_exception(self._data)
  File "/home/hardikvyas/parag/frappe-bench/env/lib/python3.12/site-packages/pymysql/err.py", line 150, in raise_mysql_exception
    raise errorclass(errno, errval)
pymysql.err.OperationalError: (1698, "Access denied for user '_10095d3054764b4c'@'localhost'")
2025-07-15 08:01:26,424 ERROR scheduler Exception in Enqueue Events for Site xyz.com
Traceback (most recent call last):
  File "/home/hardikvyas/parag/frappe-bench/apps/frappe/frappe/utils/scheduler.py", line 99, in enqueue_events_for_site
    if is_scheduler_inactive():
       ^^^^^^^^^^^^^^^^^^^^^^^
  File "/home/hardikvyas/parag/frappe-bench/apps/frappe/frappe/utils/scheduler.py", line 143, in is_scheduler_inactive
    if is_scheduler_disabled(verbose=verbose):
       ^^^^^^^^^^^^^^^^^^^^^^^^^^^^^^^^^^^^^^
  File "/home/hardikvyas/parag/frappe-bench/apps/frappe/frappe/utils/scheduler.py", line 156, in is_scheduler_disabled
    frappe.db.get_single_value("System Settings", "enable_scheduler")
  File "/home/hardikvyas/parag/frappe-bench/apps/frappe/frappe/database/database.py", line 836, in get_single_value
    ).run()
      ^^^^^
  File "/home/hardikvyas/parag/frappe-bench/apps/frappe/frappe/query_builder/utils.py", line 87, in execute_query
    result = frappe.db.sql(query, params, *args, **kwargs)  # nosemgrep
             ^^^^^^^^^^^^^^^^^^^^^^^^^^^^^^^^^^^^^^^^^^^^^
  File "/home/hardikvyas/parag/frappe-bench/apps/frappe/frappe/database/database.py", line 207, in sql
    self.connect()
  File "/home/hardikvyas/parag/frappe-bench/apps/frappe/frappe/database/database.py", line 112, in connect
    self._conn: "MariadbConnection" | "PostgresConnection" = self.get_connection()
                                                             ^^^^^^^^^^^^^^^^^^^^^
  File "/home/hardikvyas/parag/frappe-bench/apps/frappe/frappe/database/mariadb/database.py", line 108, in get_connection
    conn = self._get_connection()
           ^^^^^^^^^^^^^^^^^^^^^^
  File "/home/hardikvyas/parag/frappe-bench/apps/frappe/frappe/database/mariadb/database.py", line 114, in _get_connection
    return self.create_connection()
           ^^^^^^^^^^^^^^^^^^^^^^^^
  File "/home/hardikvyas/parag/frappe-bench/apps/frappe/frappe/database/mariadb/database.py", line 117, in create_connection
    return pymysql.connect(**self.get_connection_settings())
           ^^^^^^^^^^^^^^^^^^^^^^^^^^^^^^^^^^^^^^^^^^^^^^^^^
  File "/home/hardikvyas/parag/frappe-bench/env/lib/python3.12/site-packages/pymysql/connections.py", line 361, in __init__
    self.connect()
  File "/home/hardikvyas/parag/frappe-bench/env/lib/python3.12/site-packages/pymysql/connections.py", line 669, in connect
    self._request_authentication()
  File "/home/hardikvyas/parag/frappe-bench/env/lib/python3.12/site-packages/pymysql/connections.py", line 957, in _request_authentication
    auth_packet = self._read_packet()
                  ^^^^^^^^^^^^^^^^^^^
  File "/home/hardikvyas/parag/frappe-bench/env/lib/python3.12/site-packages/pymysql/connections.py", line 775, in _read_packet
    packet.raise_for_error()
  File "/home/hardikvyas/parag/frappe-bench/env/lib/python3.12/site-packages/pymysql/protocol.py", line 219, in raise_for_error
    err.raise_mysql_exception(self._data)
  File "/home/hardikvyas/parag/frappe-bench/env/lib/python3.12/site-packages/pymysql/err.py", line 150, in raise_mysql_exception
    raise errorclass(errno, errval)
pymysql.err.OperationalError: (1698, "Access denied for user '_10095d3054764b4c'@'localhost'")
2025-07-15 08:02:20,427 ERROR scheduler Exception in Enqueue Events for Site xyz.com
Traceback (most recent call last):
  File "/home/hardikvyas/parag/frappe-bench/apps/frappe/frappe/utils/scheduler.py", line 99, in enqueue_events_for_site
    if is_scheduler_inactive():
       ^^^^^^^^^^^^^^^^^^^^^^^
  File "/home/hardikvyas/parag/frappe-bench/apps/frappe/frappe/utils/scheduler.py", line 143, in is_scheduler_inactive
    if is_scheduler_disabled(verbose=verbose):
       ^^^^^^^^^^^^^^^^^^^^^^^^^^^^^^^^^^^^^^
  File "/home/hardikvyas/parag/frappe-bench/apps/frappe/frappe/utils/scheduler.py", line 156, in is_scheduler_disabled
    frappe.db.get_single_value("System Settings", "enable_scheduler")
  File "/home/hardikvyas/parag/frappe-bench/apps/frappe/frappe/database/database.py", line 836, in get_single_value
    ).run()
      ^^^^^
  File "/home/hardikvyas/parag/frappe-bench/apps/frappe/frappe/query_builder/utils.py", line 87, in execute_query
    result = frappe.db.sql(query, params, *args, **kwargs)  # nosemgrep
             ^^^^^^^^^^^^^^^^^^^^^^^^^^^^^^^^^^^^^^^^^^^^^
  File "/home/hardikvyas/parag/frappe-bench/apps/frappe/frappe/database/database.py", line 207, in sql
    self.connect()
  File "/home/hardikvyas/parag/frappe-bench/apps/frappe/frappe/database/database.py", line 112, in connect
    self._conn: "MariadbConnection" | "PostgresConnection" = self.get_connection()
                                                             ^^^^^^^^^^^^^^^^^^^^^
  File "/home/hardikvyas/parag/frappe-bench/apps/frappe/frappe/database/mariadb/database.py", line 108, in get_connection
    conn = self._get_connection()
           ^^^^^^^^^^^^^^^^^^^^^^
  File "/home/hardikvyas/parag/frappe-bench/apps/frappe/frappe/database/mariadb/database.py", line 114, in _get_connection
    return self.create_connection()
           ^^^^^^^^^^^^^^^^^^^^^^^^
  File "/home/hardikvyas/parag/frappe-bench/apps/frappe/frappe/database/mariadb/database.py", line 117, in create_connection
    return pymysql.connect(**self.get_connection_settings())
           ^^^^^^^^^^^^^^^^^^^^^^^^^^^^^^^^^^^^^^^^^^^^^^^^^
  File "/home/hardikvyas/parag/frappe-bench/env/lib/python3.12/site-packages/pymysql/connections.py", line 361, in __init__
    self.connect()
  File "/home/hardikvyas/parag/frappe-bench/env/lib/python3.12/site-packages/pymysql/connections.py", line 669, in connect
    self._request_authentication()
  File "/home/hardikvyas/parag/frappe-bench/env/lib/python3.12/site-packages/pymysql/connections.py", line 957, in _request_authentication
    auth_packet = self._read_packet()
                  ^^^^^^^^^^^^^^^^^^^
  File "/home/hardikvyas/parag/frappe-bench/env/lib/python3.12/site-packages/pymysql/connections.py", line 775, in _read_packet
    packet.raise_for_error()
  File "/home/hardikvyas/parag/frappe-bench/env/lib/python3.12/site-packages/pymysql/protocol.py", line 219, in raise_for_error
    err.raise_mysql_exception(self._data)
  File "/home/hardikvyas/parag/frappe-bench/env/lib/python3.12/site-packages/pymysql/err.py", line 150, in raise_mysql_exception
    raise errorclass(errno, errval)
pymysql.err.OperationalError: (1698, "Access denied for user '_10095d3054764b4c'@'localhost'")
2025-07-15 08:03:14,723 ERROR scheduler Exception in Enqueue Events for Site xyz.com
Traceback (most recent call last):
  File "/home/hardikvyas/parag/frappe-bench/apps/frappe/frappe/utils/scheduler.py", line 99, in enqueue_events_for_site
    if is_scheduler_inactive():
       ^^^^^^^^^^^^^^^^^^^^^^^
  File "/home/hardikvyas/parag/frappe-bench/apps/frappe/frappe/utils/scheduler.py", line 143, in is_scheduler_inactive
    if is_scheduler_disabled(verbose=verbose):
       ^^^^^^^^^^^^^^^^^^^^^^^^^^^^^^^^^^^^^^
  File "/home/hardikvyas/parag/frappe-bench/apps/frappe/frappe/utils/scheduler.py", line 156, in is_scheduler_disabled
    frappe.db.get_single_value("System Settings", "enable_scheduler")
  File "/home/hardikvyas/parag/frappe-bench/apps/frappe/frappe/database/database.py", line 836, in get_single_value
    ).run()
      ^^^^^
  File "/home/hardikvyas/parag/frappe-bench/apps/frappe/frappe/query_builder/utils.py", line 87, in execute_query
    result = frappe.db.sql(query, params, *args, **kwargs)  # nosemgrep
             ^^^^^^^^^^^^^^^^^^^^^^^^^^^^^^^^^^^^^^^^^^^^^
  File "/home/hardikvyas/parag/frappe-bench/apps/frappe/frappe/database/database.py", line 207, in sql
    self.connect()
  File "/home/hardikvyas/parag/frappe-bench/apps/frappe/frappe/database/database.py", line 112, in connect
    self._conn: "MariadbConnection" | "PostgresConnection" = self.get_connection()
                                                             ^^^^^^^^^^^^^^^^^^^^^
  File "/home/hardikvyas/parag/frappe-bench/apps/frappe/frappe/database/mariadb/database.py", line 108, in get_connection
    conn = self._get_connection()
           ^^^^^^^^^^^^^^^^^^^^^^
  File "/home/hardikvyas/parag/frappe-bench/apps/frappe/frappe/database/mariadb/database.py", line 114, in _get_connection
    return self.create_connection()
           ^^^^^^^^^^^^^^^^^^^^^^^^
  File "/home/hardikvyas/parag/frappe-bench/apps/frappe/frappe/database/mariadb/database.py", line 117, in create_connection
    return pymysql.connect(**self.get_connection_settings())
           ^^^^^^^^^^^^^^^^^^^^^^^^^^^^^^^^^^^^^^^^^^^^^^^^^
  File "/home/hardikvyas/parag/frappe-bench/env/lib/python3.12/site-packages/pymysql/connections.py", line 361, in __init__
    self.connect()
  File "/home/hardikvyas/parag/frappe-bench/env/lib/python3.12/site-packages/pymysql/connections.py", line 669, in connect
    self._request_authentication()
  File "/home/hardikvyas/parag/frappe-bench/env/lib/python3.12/site-packages/pymysql/connections.py", line 957, in _request_authentication
    auth_packet = self._read_packet()
                  ^^^^^^^^^^^^^^^^^^^
  File "/home/hardikvyas/parag/frappe-bench/env/lib/python3.12/site-packages/pymysql/connections.py", line 775, in _read_packet
    packet.raise_for_error()
  File "/home/hardikvyas/parag/frappe-bench/env/lib/python3.12/site-packages/pymysql/protocol.py", line 219, in raise_for_error
    err.raise_mysql_exception(self._data)
  File "/home/hardikvyas/parag/frappe-bench/env/lib/python3.12/site-packages/pymysql/err.py", line 150, in raise_mysql_exception
    raise errorclass(errno, errval)
pymysql.err.OperationalError: (1698, "Access denied for user '_10095d3054764b4c'@'localhost'")
2025-07-15 08:04:11,819 ERROR scheduler Exception in Enqueue Events for Site xyz.com
Traceback (most recent call last):
  File "/home/hardikvyas/parag/frappe-bench/apps/frappe/frappe/utils/scheduler.py", line 99, in enqueue_events_for_site
    if is_scheduler_inactive():
       ^^^^^^^^^^^^^^^^^^^^^^^
  File "/home/hardikvyas/parag/frappe-bench/apps/frappe/frappe/utils/scheduler.py", line 143, in is_scheduler_inactive
    if is_scheduler_disabled(verbose=verbose):
       ^^^^^^^^^^^^^^^^^^^^^^^^^^^^^^^^^^^^^^
  File "/home/hardikvyas/parag/frappe-bench/apps/frappe/frappe/utils/scheduler.py", line 156, in is_scheduler_disabled
    frappe.db.get_single_value("System Settings", "enable_scheduler")
  File "/home/hardikvyas/parag/frappe-bench/apps/frappe/frappe/database/database.py", line 836, in get_single_value
    ).run()
      ^^^^^
  File "/home/hardikvyas/parag/frappe-bench/apps/frappe/frappe/query_builder/utils.py", line 87, in execute_query
    result = frappe.db.sql(query, params, *args, **kwargs)  # nosemgrep
             ^^^^^^^^^^^^^^^^^^^^^^^^^^^^^^^^^^^^^^^^^^^^^
  File "/home/hardikvyas/parag/frappe-bench/apps/frappe/frappe/database/database.py", line 207, in sql
    self.connect()
  File "/home/hardikvyas/parag/frappe-bench/apps/frappe/frappe/database/database.py", line 112, in connect
    self._conn: "MariadbConnection" | "PostgresConnection" = self.get_connection()
                                                             ^^^^^^^^^^^^^^^^^^^^^
  File "/home/hardikvyas/parag/frappe-bench/apps/frappe/frappe/database/mariadb/database.py", line 108, in get_connection
    conn = self._get_connection()
           ^^^^^^^^^^^^^^^^^^^^^^
  File "/home/hardikvyas/parag/frappe-bench/apps/frappe/frappe/database/mariadb/database.py", line 114, in _get_connection
    return self.create_connection()
           ^^^^^^^^^^^^^^^^^^^^^^^^
  File "/home/hardikvyas/parag/frappe-bench/apps/frappe/frappe/database/mariadb/database.py", line 117, in create_connection
    return pymysql.connect(**self.get_connection_settings())
           ^^^^^^^^^^^^^^^^^^^^^^^^^^^^^^^^^^^^^^^^^^^^^^^^^
  File "/home/hardikvyas/parag/frappe-bench/env/lib/python3.12/site-packages/pymysql/connections.py", line 361, in __init__
    self.connect()
  File "/home/hardikvyas/parag/frappe-bench/env/lib/python3.12/site-packages/pymysql/connections.py", line 669, in connect
    self._request_authentication()
  File "/home/hardikvyas/parag/frappe-bench/env/lib/python3.12/site-packages/pymysql/connections.py", line 957, in _request_authentication
    auth_packet = self._read_packet()
                  ^^^^^^^^^^^^^^^^^^^
  File "/home/hardikvyas/parag/frappe-bench/env/lib/python3.12/site-packages/pymysql/connections.py", line 775, in _read_packet
    packet.raise_for_error()
  File "/home/hardikvyas/parag/frappe-bench/env/lib/python3.12/site-packages/pymysql/protocol.py", line 219, in raise_for_error
    err.raise_mysql_exception(self._data)
  File "/home/hardikvyas/parag/frappe-bench/env/lib/python3.12/site-packages/pymysql/err.py", line 150, in raise_mysql_exception
    raise errorclass(errno, errval)
pymysql.err.OperationalError: (1698, "Access denied for user '_10095d3054764b4c'@'localhost'")
2025-07-15 08:05:05,882 ERROR scheduler Exception in Enqueue Events for Site xyz.com
Traceback (most recent call last):
  File "/home/hardikvyas/parag/frappe-bench/apps/frappe/frappe/utils/scheduler.py", line 99, in enqueue_events_for_site
    if is_scheduler_inactive():
       ^^^^^^^^^^^^^^^^^^^^^^^
  File "/home/hardikvyas/parag/frappe-bench/apps/frappe/frappe/utils/scheduler.py", line 143, in is_scheduler_inactive
    if is_scheduler_disabled(verbose=verbose):
       ^^^^^^^^^^^^^^^^^^^^^^^^^^^^^^^^^^^^^^
  File "/home/hardikvyas/parag/frappe-bench/apps/frappe/frappe/utils/scheduler.py", line 156, in is_scheduler_disabled
    frappe.db.get_single_value("System Settings", "enable_scheduler")
  File "/home/hardikvyas/parag/frappe-bench/apps/frappe/frappe/database/database.py", line 836, in get_single_value
    ).run()
      ^^^^^
  File "/home/hardikvyas/parag/frappe-bench/apps/frappe/frappe/query_builder/utils.py", line 87, in execute_query
    result = frappe.db.sql(query, params, *args, **kwargs)  # nosemgrep
             ^^^^^^^^^^^^^^^^^^^^^^^^^^^^^^^^^^^^^^^^^^^^^
  File "/home/hardikvyas/parag/frappe-bench/apps/frappe/frappe/database/database.py", line 207, in sql
    self.connect()
  File "/home/hardikvyas/parag/frappe-bench/apps/frappe/frappe/database/database.py", line 112, in connect
    self._conn: "MariadbConnection" | "PostgresConnection" = self.get_connection()
                                                             ^^^^^^^^^^^^^^^^^^^^^
  File "/home/hardikvyas/parag/frappe-bench/apps/frappe/frappe/database/mariadb/database.py", line 108, in get_connection
    conn = self._get_connection()
           ^^^^^^^^^^^^^^^^^^^^^^
  File "/home/hardikvyas/parag/frappe-bench/apps/frappe/frappe/database/mariadb/database.py", line 114, in _get_connection
    return self.create_connection()
           ^^^^^^^^^^^^^^^^^^^^^^^^
  File "/home/hardikvyas/parag/frappe-bench/apps/frappe/frappe/database/mariadb/database.py", line 117, in create_connection
    return pymysql.connect(**self.get_connection_settings())
           ^^^^^^^^^^^^^^^^^^^^^^^^^^^^^^^^^^^^^^^^^^^^^^^^^
  File "/home/hardikvyas/parag/frappe-bench/env/lib/python3.12/site-packages/pymysql/connections.py", line 361, in __init__
    self.connect()
  File "/home/hardikvyas/parag/frappe-bench/env/lib/python3.12/site-packages/pymysql/connections.py", line 669, in connect
    self._request_authentication()
  File "/home/hardikvyas/parag/frappe-bench/env/lib/python3.12/site-packages/pymysql/connections.py", line 957, in _request_authentication
    auth_packet = self._read_packet()
                  ^^^^^^^^^^^^^^^^^^^
  File "/home/hardikvyas/parag/frappe-bench/env/lib/python3.12/site-packages/pymysql/connections.py", line 775, in _read_packet
    packet.raise_for_error()
  File "/home/hardikvyas/parag/frappe-bench/env/lib/python3.12/site-packages/pymysql/protocol.py", line 219, in raise_for_error
    err.raise_mysql_exception(self._data)
  File "/home/hardikvyas/parag/frappe-bench/env/lib/python3.12/site-packages/pymysql/err.py", line 150, in raise_mysql_exception
    raise errorclass(errno, errval)
pymysql.err.OperationalError: (1698, "Access denied for user '_10095d3054764b4c'@'localhost'")
2025-07-15 08:05:59,939 ERROR scheduler Exception in Enqueue Events for Site xyz.com
Traceback (most recent call last):
  File "/home/hardikvyas/parag/frappe-bench/apps/frappe/frappe/utils/scheduler.py", line 99, in enqueue_events_for_site
    if is_scheduler_inactive():
       ^^^^^^^^^^^^^^^^^^^^^^^
  File "/home/hardikvyas/parag/frappe-bench/apps/frappe/frappe/utils/scheduler.py", line 143, in is_scheduler_inactive
    if is_scheduler_disabled(verbose=verbose):
       ^^^^^^^^^^^^^^^^^^^^^^^^^^^^^^^^^^^^^^
  File "/home/hardikvyas/parag/frappe-bench/apps/frappe/frappe/utils/scheduler.py", line 156, in is_scheduler_disabled
    frappe.db.get_single_value("System Settings", "enable_scheduler")
  File "/home/hardikvyas/parag/frappe-bench/apps/frappe/frappe/database/database.py", line 836, in get_single_value
    ).run()
      ^^^^^
  File "/home/hardikvyas/parag/frappe-bench/apps/frappe/frappe/query_builder/utils.py", line 87, in execute_query
    result = frappe.db.sql(query, params, *args, **kwargs)  # nosemgrep
             ^^^^^^^^^^^^^^^^^^^^^^^^^^^^^^^^^^^^^^^^^^^^^
  File "/home/hardikvyas/parag/frappe-bench/apps/frappe/frappe/database/database.py", line 207, in sql
    self.connect()
  File "/home/hardikvyas/parag/frappe-bench/apps/frappe/frappe/database/database.py", line 112, in connect
    self._conn: "MariadbConnection" | "PostgresConnection" = self.get_connection()
                                                             ^^^^^^^^^^^^^^^^^^^^^
  File "/home/hardikvyas/parag/frappe-bench/apps/frappe/frappe/database/mariadb/database.py", line 108, in get_connection
    conn = self._get_connection()
           ^^^^^^^^^^^^^^^^^^^^^^
  File "/home/hardikvyas/parag/frappe-bench/apps/frappe/frappe/database/mariadb/database.py", line 114, in _get_connection
    return self.create_connection()
           ^^^^^^^^^^^^^^^^^^^^^^^^
  File "/home/hardikvyas/parag/frappe-bench/apps/frappe/frappe/database/mariadb/database.py", line 117, in create_connection
    return pymysql.connect(**self.get_connection_settings())
           ^^^^^^^^^^^^^^^^^^^^^^^^^^^^^^^^^^^^^^^^^^^^^^^^^
  File "/home/hardikvyas/parag/frappe-bench/env/lib/python3.12/site-packages/pymysql/connections.py", line 361, in __init__
    self.connect()
  File "/home/hardikvyas/parag/frappe-bench/env/lib/python3.12/site-packages/pymysql/connections.py", line 669, in connect
    self._request_authentication()
  File "/home/hardikvyas/parag/frappe-bench/env/lib/python3.12/site-packages/pymysql/connections.py", line 957, in _request_authentication
    auth_packet = self._read_packet()
                  ^^^^^^^^^^^^^^^^^^^
  File "/home/hardikvyas/parag/frappe-bench/env/lib/python3.12/site-packages/pymysql/connections.py", line 775, in _read_packet
    packet.raise_for_error()
  File "/home/hardikvyas/parag/frappe-bench/env/lib/python3.12/site-packages/pymysql/protocol.py", line 219, in raise_for_error
    err.raise_mysql_exception(self._data)
  File "/home/hardikvyas/parag/frappe-bench/env/lib/python3.12/site-packages/pymysql/err.py", line 150, in raise_mysql_exception
    raise errorclass(errno, errval)
pymysql.err.OperationalError: (1698, "Access denied for user '_10095d3054764b4c'@'localhost'")
2025-07-15 08:06:54,368 ERROR scheduler Exception in Enqueue Events for Site xyz.com
Traceback (most recent call last):
  File "/home/hardikvyas/parag/frappe-bench/apps/frappe/frappe/utils/scheduler.py", line 99, in enqueue_events_for_site
    if is_scheduler_inactive():
       ^^^^^^^^^^^^^^^^^^^^^^^
  File "/home/hardikvyas/parag/frappe-bench/apps/frappe/frappe/utils/scheduler.py", line 143, in is_scheduler_inactive
    if is_scheduler_disabled(verbose=verbose):
       ^^^^^^^^^^^^^^^^^^^^^^^^^^^^^^^^^^^^^^
  File "/home/hardikvyas/parag/frappe-bench/apps/frappe/frappe/utils/scheduler.py", line 156, in is_scheduler_disabled
    frappe.db.get_single_value("System Settings", "enable_scheduler")
  File "/home/hardikvyas/parag/frappe-bench/apps/frappe/frappe/database/database.py", line 836, in get_single_value
    ).run()
      ^^^^^
  File "/home/hardikvyas/parag/frappe-bench/apps/frappe/frappe/query_builder/utils.py", line 87, in execute_query
    result = frappe.db.sql(query, params, *args, **kwargs)  # nosemgrep
             ^^^^^^^^^^^^^^^^^^^^^^^^^^^^^^^^^^^^^^^^^^^^^
  File "/home/hardikvyas/parag/frappe-bench/apps/frappe/frappe/database/database.py", line 207, in sql
    self.connect()
  File "/home/hardikvyas/parag/frappe-bench/apps/frappe/frappe/database/database.py", line 112, in connect
    self._conn: "MariadbConnection" | "PostgresConnection" = self.get_connection()
                                                             ^^^^^^^^^^^^^^^^^^^^^
  File "/home/hardikvyas/parag/frappe-bench/apps/frappe/frappe/database/mariadb/database.py", line 108, in get_connection
    conn = self._get_connection()
           ^^^^^^^^^^^^^^^^^^^^^^
  File "/home/hardikvyas/parag/frappe-bench/apps/frappe/frappe/database/mariadb/database.py", line 114, in _get_connection
    return self.create_connection()
           ^^^^^^^^^^^^^^^^^^^^^^^^
  File "/home/hardikvyas/parag/frappe-bench/apps/frappe/frappe/database/mariadb/database.py", line 117, in create_connection
    return pymysql.connect(**self.get_connection_settings())
           ^^^^^^^^^^^^^^^^^^^^^^^^^^^^^^^^^^^^^^^^^^^^^^^^^
  File "/home/hardikvyas/parag/frappe-bench/env/lib/python3.12/site-packages/pymysql/connections.py", line 361, in __init__
    self.connect()
  File "/home/hardikvyas/parag/frappe-bench/env/lib/python3.12/site-packages/pymysql/connections.py", line 669, in connect
    self._request_authentication()
  File "/home/hardikvyas/parag/frappe-bench/env/lib/python3.12/site-packages/pymysql/connections.py", line 957, in _request_authentication
    auth_packet = self._read_packet()
                  ^^^^^^^^^^^^^^^^^^^
  File "/home/hardikvyas/parag/frappe-bench/env/lib/python3.12/site-packages/pymysql/connections.py", line 775, in _read_packet
    packet.raise_for_error()
  File "/home/hardikvyas/parag/frappe-bench/env/lib/python3.12/site-packages/pymysql/protocol.py", line 219, in raise_for_error
    err.raise_mysql_exception(self._data)
  File "/home/hardikvyas/parag/frappe-bench/env/lib/python3.12/site-packages/pymysql/err.py", line 150, in raise_mysql_exception
    raise errorclass(errno, errval)
pymysql.err.OperationalError: (1698, "Access denied for user '_10095d3054764b4c'@'localhost'")
2025-07-15 08:07:48,369 ERROR scheduler Exception in Enqueue Events for Site xyz.com
Traceback (most recent call last):
  File "/home/hardikvyas/parag/frappe-bench/apps/frappe/frappe/utils/scheduler.py", line 99, in enqueue_events_for_site
    if is_scheduler_inactive():
       ^^^^^^^^^^^^^^^^^^^^^^^
  File "/home/hardikvyas/parag/frappe-bench/apps/frappe/frappe/utils/scheduler.py", line 143, in is_scheduler_inactive
    if is_scheduler_disabled(verbose=verbose):
       ^^^^^^^^^^^^^^^^^^^^^^^^^^^^^^^^^^^^^^
  File "/home/hardikvyas/parag/frappe-bench/apps/frappe/frappe/utils/scheduler.py", line 156, in is_scheduler_disabled
    frappe.db.get_single_value("System Settings", "enable_scheduler")
  File "/home/hardikvyas/parag/frappe-bench/apps/frappe/frappe/database/database.py", line 836, in get_single_value
    ).run()
      ^^^^^
  File "/home/hardikvyas/parag/frappe-bench/apps/frappe/frappe/query_builder/utils.py", line 87, in execute_query
    result = frappe.db.sql(query, params, *args, **kwargs)  # nosemgrep
             ^^^^^^^^^^^^^^^^^^^^^^^^^^^^^^^^^^^^^^^^^^^^^
  File "/home/hardikvyas/parag/frappe-bench/apps/frappe/frappe/database/database.py", line 207, in sql
    self.connect()
  File "/home/hardikvyas/parag/frappe-bench/apps/frappe/frappe/database/database.py", line 112, in connect
    self._conn: "MariadbConnection" | "PostgresConnection" = self.get_connection()
                                                             ^^^^^^^^^^^^^^^^^^^^^
  File "/home/hardikvyas/parag/frappe-bench/apps/frappe/frappe/database/mariadb/database.py", line 108, in get_connection
    conn = self._get_connection()
           ^^^^^^^^^^^^^^^^^^^^^^
  File "/home/hardikvyas/parag/frappe-bench/apps/frappe/frappe/database/mariadb/database.py", line 114, in _get_connection
    return self.create_connection()
           ^^^^^^^^^^^^^^^^^^^^^^^^
  File "/home/hardikvyas/parag/frappe-bench/apps/frappe/frappe/database/mariadb/database.py", line 117, in create_connection
    return pymysql.connect(**self.get_connection_settings())
           ^^^^^^^^^^^^^^^^^^^^^^^^^^^^^^^^^^^^^^^^^^^^^^^^^
  File "/home/hardikvyas/parag/frappe-bench/env/lib/python3.12/site-packages/pymysql/connections.py", line 361, in __init__
    self.connect()
  File "/home/hardikvyas/parag/frappe-bench/env/lib/python3.12/site-packages/pymysql/connections.py", line 669, in connect
    self._request_authentication()
  File "/home/hardikvyas/parag/frappe-bench/env/lib/python3.12/site-packages/pymysql/connections.py", line 957, in _request_authentication
    auth_packet = self._read_packet()
                  ^^^^^^^^^^^^^^^^^^^
  File "/home/hardikvyas/parag/frappe-bench/env/lib/python3.12/site-packages/pymysql/connections.py", line 775, in _read_packet
    packet.raise_for_error()
  File "/home/hardikvyas/parag/frappe-bench/env/lib/python3.12/site-packages/pymysql/protocol.py", line 219, in raise_for_error
    err.raise_mysql_exception(self._data)
  File "/home/hardikvyas/parag/frappe-bench/env/lib/python3.12/site-packages/pymysql/err.py", line 150, in raise_mysql_exception
    raise errorclass(errno, errval)
pymysql.err.OperationalError: (1698, "Access denied for user '_10095d3054764b4c'@'localhost'")
2025-07-15 08:08:45,440 ERROR scheduler Exception in Enqueue Events for Site xyz.com
Traceback (most recent call last):
  File "/home/hardikvyas/parag/frappe-bench/apps/frappe/frappe/utils/scheduler.py", line 99, in enqueue_events_for_site
    if is_scheduler_inactive():
       ^^^^^^^^^^^^^^^^^^^^^^^
  File "/home/hardikvyas/parag/frappe-bench/apps/frappe/frappe/utils/scheduler.py", line 143, in is_scheduler_inactive
    if is_scheduler_disabled(verbose=verbose):
       ^^^^^^^^^^^^^^^^^^^^^^^^^^^^^^^^^^^^^^
  File "/home/hardikvyas/parag/frappe-bench/apps/frappe/frappe/utils/scheduler.py", line 156, in is_scheduler_disabled
    frappe.db.get_single_value("System Settings", "enable_scheduler")
  File "/home/hardikvyas/parag/frappe-bench/apps/frappe/frappe/database/database.py", line 836, in get_single_value
    ).run()
      ^^^^^
  File "/home/hardikvyas/parag/frappe-bench/apps/frappe/frappe/query_builder/utils.py", line 87, in execute_query
    result = frappe.db.sql(query, params, *args, **kwargs)  # nosemgrep
             ^^^^^^^^^^^^^^^^^^^^^^^^^^^^^^^^^^^^^^^^^^^^^
  File "/home/hardikvyas/parag/frappe-bench/apps/frappe/frappe/database/database.py", line 207, in sql
    self.connect()
  File "/home/hardikvyas/parag/frappe-bench/apps/frappe/frappe/database/database.py", line 112, in connect
    self._conn: "MariadbConnection" | "PostgresConnection" = self.get_connection()
                                                             ^^^^^^^^^^^^^^^^^^^^^
  File "/home/hardikvyas/parag/frappe-bench/apps/frappe/frappe/database/mariadb/database.py", line 108, in get_connection
    conn = self._get_connection()
           ^^^^^^^^^^^^^^^^^^^^^^
  File "/home/hardikvyas/parag/frappe-bench/apps/frappe/frappe/database/mariadb/database.py", line 114, in _get_connection
    return self.create_connection()
           ^^^^^^^^^^^^^^^^^^^^^^^^
  File "/home/hardikvyas/parag/frappe-bench/apps/frappe/frappe/database/mariadb/database.py", line 117, in create_connection
    return pymysql.connect(**self.get_connection_settings())
           ^^^^^^^^^^^^^^^^^^^^^^^^^^^^^^^^^^^^^^^^^^^^^^^^^
  File "/home/hardikvyas/parag/frappe-bench/env/lib/python3.12/site-packages/pymysql/connections.py", line 361, in __init__
    self.connect()
  File "/home/hardikvyas/parag/frappe-bench/env/lib/python3.12/site-packages/pymysql/connections.py", line 669, in connect
    self._request_authentication()
  File "/home/hardikvyas/parag/frappe-bench/env/lib/python3.12/site-packages/pymysql/connections.py", line 957, in _request_authentication
    auth_packet = self._read_packet()
                  ^^^^^^^^^^^^^^^^^^^
  File "/home/hardikvyas/parag/frappe-bench/env/lib/python3.12/site-packages/pymysql/connections.py", line 775, in _read_packet
    packet.raise_for_error()
  File "/home/hardikvyas/parag/frappe-bench/env/lib/python3.12/site-packages/pymysql/protocol.py", line 219, in raise_for_error
    err.raise_mysql_exception(self._data)
  File "/home/hardikvyas/parag/frappe-bench/env/lib/python3.12/site-packages/pymysql/err.py", line 150, in raise_mysql_exception
    raise errorclass(errno, errval)
pymysql.err.OperationalError: (1698, "Access denied for user '_10095d3054764b4c'@'localhost'")
2025-07-15 08:09:39,708 ERROR scheduler Exception in Enqueue Events for Site xyz.com
Traceback (most recent call last):
  File "/home/hardikvyas/parag/frappe-bench/apps/frappe/frappe/utils/scheduler.py", line 99, in enqueue_events_for_site
    if is_scheduler_inactive():
       ^^^^^^^^^^^^^^^^^^^^^^^
  File "/home/hardikvyas/parag/frappe-bench/apps/frappe/frappe/utils/scheduler.py", line 143, in is_scheduler_inactive
    if is_scheduler_disabled(verbose=verbose):
       ^^^^^^^^^^^^^^^^^^^^^^^^^^^^^^^^^^^^^^
  File "/home/hardikvyas/parag/frappe-bench/apps/frappe/frappe/utils/scheduler.py", line 156, in is_scheduler_disabled
    frappe.db.get_single_value("System Settings", "enable_scheduler")
  File "/home/hardikvyas/parag/frappe-bench/apps/frappe/frappe/database/database.py", line 836, in get_single_value
    ).run()
      ^^^^^
  File "/home/hardikvyas/parag/frappe-bench/apps/frappe/frappe/query_builder/utils.py", line 87, in execute_query
    result = frappe.db.sql(query, params, *args, **kwargs)  # nosemgrep
             ^^^^^^^^^^^^^^^^^^^^^^^^^^^^^^^^^^^^^^^^^^^^^
  File "/home/hardikvyas/parag/frappe-bench/apps/frappe/frappe/database/database.py", line 207, in sql
    self.connect()
  File "/home/hardikvyas/parag/frappe-bench/apps/frappe/frappe/database/database.py", line 112, in connect
    self._conn: "MariadbConnection" | "PostgresConnection" = self.get_connection()
                                                             ^^^^^^^^^^^^^^^^^^^^^
  File "/home/hardikvyas/parag/frappe-bench/apps/frappe/frappe/database/mariadb/database.py", line 108, in get_connection
    conn = self._get_connection()
           ^^^^^^^^^^^^^^^^^^^^^^
  File "/home/hardikvyas/parag/frappe-bench/apps/frappe/frappe/database/mariadb/database.py", line 114, in _get_connection
    return self.create_connection()
           ^^^^^^^^^^^^^^^^^^^^^^^^
  File "/home/hardikvyas/parag/frappe-bench/apps/frappe/frappe/database/mariadb/database.py", line 117, in create_connection
    return pymysql.connect(**self.get_connection_settings())
           ^^^^^^^^^^^^^^^^^^^^^^^^^^^^^^^^^^^^^^^^^^^^^^^^^
  File "/home/hardikvyas/parag/frappe-bench/env/lib/python3.12/site-packages/pymysql/connections.py", line 361, in __init__
    self.connect()
  File "/home/hardikvyas/parag/frappe-bench/env/lib/python3.12/site-packages/pymysql/connections.py", line 669, in connect
    self._request_authentication()
  File "/home/hardikvyas/parag/frappe-bench/env/lib/python3.12/site-packages/pymysql/connections.py", line 957, in _request_authentication
    auth_packet = self._read_packet()
                  ^^^^^^^^^^^^^^^^^^^
  File "/home/hardikvyas/parag/frappe-bench/env/lib/python3.12/site-packages/pymysql/connections.py", line 775, in _read_packet
    packet.raise_for_error()
  File "/home/hardikvyas/parag/frappe-bench/env/lib/python3.12/site-packages/pymysql/protocol.py", line 219, in raise_for_error
    err.raise_mysql_exception(self._data)
  File "/home/hardikvyas/parag/frappe-bench/env/lib/python3.12/site-packages/pymysql/err.py", line 150, in raise_mysql_exception
    raise errorclass(errno, errval)
pymysql.err.OperationalError: (1698, "Access denied for user '_10095d3054764b4c'@'localhost'")
2025-07-15 08:11:03,504 ERROR scheduler Exception in Enqueue Events for Site xyz.com
Traceback (most recent call last):
  File "/home/hardikvyas/parag/frappe-bench/apps/frappe/frappe/utils/scheduler.py", line 99, in enqueue_events_for_site
    if is_scheduler_inactive():
       ^^^^^^^^^^^^^^^^^^^^^^^
  File "/home/hardikvyas/parag/frappe-bench/apps/frappe/frappe/utils/scheduler.py", line 143, in is_scheduler_inactive
    if is_scheduler_disabled(verbose=verbose):
       ^^^^^^^^^^^^^^^^^^^^^^^^^^^^^^^^^^^^^^
  File "/home/hardikvyas/parag/frappe-bench/apps/frappe/frappe/utils/scheduler.py", line 156, in is_scheduler_disabled
    frappe.db.get_single_value("System Settings", "enable_scheduler")
  File "/home/hardikvyas/parag/frappe-bench/apps/frappe/frappe/database/database.py", line 836, in get_single_value
    ).run()
      ^^^^^
  File "/home/hardikvyas/parag/frappe-bench/apps/frappe/frappe/query_builder/utils.py", line 87, in execute_query
    result = frappe.db.sql(query, params, *args, **kwargs)  # nosemgrep
             ^^^^^^^^^^^^^^^^^^^^^^^^^^^^^^^^^^^^^^^^^^^^^
  File "/home/hardikvyas/parag/frappe-bench/apps/frappe/frappe/database/database.py", line 207, in sql
    self.connect()
  File "/home/hardikvyas/parag/frappe-bench/apps/frappe/frappe/database/database.py", line 112, in connect
    self._conn: "MariadbConnection" | "PostgresConnection" = self.get_connection()
                                                             ^^^^^^^^^^^^^^^^^^^^^
  File "/home/hardikvyas/parag/frappe-bench/apps/frappe/frappe/database/mariadb/database.py", line 108, in get_connection
    conn = self._get_connection()
           ^^^^^^^^^^^^^^^^^^^^^^
  File "/home/hardikvyas/parag/frappe-bench/apps/frappe/frappe/database/mariadb/database.py", line 114, in _get_connection
    return self.create_connection()
           ^^^^^^^^^^^^^^^^^^^^^^^^
  File "/home/hardikvyas/parag/frappe-bench/apps/frappe/frappe/database/mariadb/database.py", line 117, in create_connection
    return pymysql.connect(**self.get_connection_settings())
           ^^^^^^^^^^^^^^^^^^^^^^^^^^^^^^^^^^^^^^^^^^^^^^^^^
  File "/home/hardikvyas/parag/frappe-bench/env/lib/python3.12/site-packages/pymysql/connections.py", line 361, in __init__
    self.connect()
  File "/home/hardikvyas/parag/frappe-bench/env/lib/python3.12/site-packages/pymysql/connections.py", line 669, in connect
    self._request_authentication()
  File "/home/hardikvyas/parag/frappe-bench/env/lib/python3.12/site-packages/pymysql/connections.py", line 957, in _request_authentication
    auth_packet = self._read_packet()
                  ^^^^^^^^^^^^^^^^^^^
  File "/home/hardikvyas/parag/frappe-bench/env/lib/python3.12/site-packages/pymysql/connections.py", line 775, in _read_packet
    packet.raise_for_error()
  File "/home/hardikvyas/parag/frappe-bench/env/lib/python3.12/site-packages/pymysql/protocol.py", line 219, in raise_for_error
    err.raise_mysql_exception(self._data)
  File "/home/hardikvyas/parag/frappe-bench/env/lib/python3.12/site-packages/pymysql/err.py", line 150, in raise_mysql_exception
    raise errorclass(errno, errval)
pymysql.err.OperationalError: (1698, "Access denied for user '_10095d3054764b4c'@'localhost'")
